Workbook

Sheet Theo nhom SP (7-30-90d)
A1: Ads Shopee theo NHOM san pham - 3 khung thoi gian (7 / 30 / 90 ngay)
A2: ROAS sau phi = ROAS x (1 - Phi san %) - dung de chon NEN CHAY ADS O SHOP NAO cho tung nhom san pham (COGS nhu nhau o 2 shop nen khong anh huong quyet dinh). Dong TONG cuoi moi khung = ROAS blended toan bo ads shop do, khong chi 5 nhom liet ke.
A4: KHUNG 7 NGÀY (2026-07-01 -> 2026-07-07)
A5: Nhom san pham | B5: GOC HUONG THOM | F5: THE ART OF SCENT | J5: Khuyen nghi
B6: Chi phi | C6: Doanh so | D6: ROAS | E6: ROAS sau phi | F6: Chi phi | G6: Doanh so | H6: ROAS | I6: ROAS sau phi
A7: Nước Hoa | B7: =SUMIFS('Raw Data - Nhóm SP'!$E:$E,'Raw Data - Nhóm SP'!$C:$C,"Nước Hoa",'Raw Data - Nhóm SP'!$B:$B,"Aroma Story - Góc Hương Thơm",'Raw Data - Nhóm SP'!$A:$A,">="&DATE(2026,7,1),'Raw Data - Nhóm SP'!$A:$A,"<="&DATE(2026,7,7)) -> 782357 | C7: =SUMIFS('Raw Data - Nhóm SP'!$F:$F,'Raw Data - Nhóm SP'!$C:$C,"Nước Hoa",'Raw Data - Nhóm SP'!$B:$B,"Aroma Story - Góc Hương Thơm",'Raw Data - Nhóm SP'!$A:$A,">="&DATE(2026,7,1),'Raw Data - Nhóm SP'!$A:$A,"<="&DATE(2026,7,7)) -> 3028989 | D7: =IF(B7=0,0,C7/B7) -> 3.87162 | E7: =IF(B7=0,0,D7*(1-'Phí sàn theo shop'!$D$2)) -> 2.9563142 | F7: =SUMIFS('Raw Data - Nhóm SP'!$E:$E,'Raw Data - Nhóm SP'!$C:$C,"Nước Hoa",'Raw Data - Nhóm SP'!$B:$B,"Aroma Story - The Art Of Scent",'Raw Data - Nhóm SP'!$A:$A,">="&DATE(2026,7,1),'Raw Data - Nhóm SP'!$A:$A,"<="&DATE(2026,7,7)) -> 350698 | G7: =SUMIFS('Raw Data - Nhóm SP'!$F:$F,'Raw Data - Nhóm SP'!$C:$C,"Nước Hoa",'Raw Data - Nhóm SP'!$B:$B,"Aroma Story - The Art Of Scent",'Raw Data - Nhóm SP'!$A:$A,">="&DATE(2026,7,1),'Raw Data - Nhóm SP'!$A:$A,"<="&DATE(2026,7,7)) -> 590000 | H7: =IF(F7=0,0,G7/F7) -> 1.6823592 | I7: =IF(F7=0,0,H7*(1-'Phí sàn theo shop'!$D$3)) -> 1.1593287 | J7: =IF(OR(B7=0,F7=0),IF(B7=0,"Chỉ TAOS có data",IF(F7=0,"Chỉ GHT có data","-")),IF(ABS(E7-I7)/MAX(E7,I7)<0.03,"Ngang nhau -> uu tien GHT",IF(E7>I7,"Don ve GHT","Don ve TAOS"))) -> Don ve GHT
A8: Nến Thơm | B8: =SUMIFS('Raw Data - Nhóm SP'!$E:$E,'Raw Data - Nhóm SP'!$C:$C,"Nến Thơm",'Raw Data - Nhóm SP'!$B:$B,"Aroma Story - Góc Hương Thơm",'Raw Data - Nhóm SP'!$A:$A,">="&DATE(2026,7,1),'Raw Data - Nhóm SP'!$A:$A,"<="&DATE(2026,7,7)) -> 3296184 | C8: =SUMIFS('Raw Data - Nhóm SP'!$F:$F,'Raw Data - Nhóm SP'!$C:$C,"Nến Thơm",'Raw Data - Nhóm SP'!$B:$B,"Aroma Story - Góc Hương Thơm",'Raw Data - Nhóm SP'!$A:$A,">="&DATE(2026,7,1),'Raw Data - Nhóm SP'!$A:$A,"<="&DATE(2026,7,7)) -> 14557119 | D8: =IF(B8=0,0,C8/B8) -> 4.4163551 | E8: =IF(B8=0,0,D8*(1-'Phí sàn theo shop'!$D$2)) -> 3.3722662 | F8: =SUMIFS('Raw Data - Nhóm SP'!$E:$E,'Raw Data - Nhóm SP'!$C:$C,"Nến Thơm",'Raw Data - Nhóm SP'!$B:$B,"Aroma Story - The Art Of Scent",'Raw Data - Nhóm SP'!$A:$A,">="&DATE(2026,7,1),'Raw Data - Nhóm SP'!$A:$A,"<="&DATE(2026,7,7)) -> 7547659 | G8: =SUMIFS('Raw Data - Nhóm SP'!$F:$F,'Raw Data - Nhóm SP'!$C:$C,"Nến Thơm",'Raw Data - Nhóm SP'!$B:$B,"Aroma Story - The Art Of Scent",'Raw Data - Nhóm SP'!$A:$A,">="&DATE(2026,7,1),'Raw Data - Nhóm SP'!$A:$A,"<="&DATE(2026,7,7)) -> 40545860 | H8: =IF(F8=0,0,G8/F8) -> 5.3719783 | I8: =IF(F8=0,0,H8*(1-'Phí sàn theo shop'!$D$3)) -> 3.701878 | J8: =IF(OR(B8=0,F8=0),IF(B8=0,"Chỉ TAOS có data",IF(F8=0,"Chỉ GHT có data","-")),IF(ABS(E8-I8)/MAX(E8,I8)<0.03,"Ngang nhau -> uu tien GHT",IF(E8>I8,"Don ve GHT","Don ve TAOS"))) -> Don ve TAOS
A9: Tinh Dầu Khuếch Tán | B9: =SUMIFS('Raw Data - Nhóm SP'!$E:$E,'Raw Data - Nhóm SP'!$C:$C,"Tinh Dầu Khuếch Tán",'Raw Data - Nhóm SP'!$B:$B,"Aroma Story - Góc Hương Thơm",'Raw Data - Nhóm SP'!$A:$A,">="&DATE(2026,7,1),'Raw Data - Nhóm SP'!$A:$A,"<="&DATE(2026,7,7)) -> 3466476 | C9: =SUMIFS('Raw Data - Nhóm SP'!$F:$F,'Raw Data - Nhóm SP'!$C:$C,"Tinh Dầu Khuếch Tán",'Raw Data - Nhóm SP'!$B:$B,"Aroma Story - Góc Hương Thơm",'Raw Data - Nhóm SP'!$A:$A,">="&DATE(2026,7,1),'Raw Data - Nhóm SP'!$A:$A,"<="&DATE(2026,7,7)) -> 18822714 | D9: =IF(B9=0,0,C9/B9) -> 5.4299277 | E9: =IF(B9=0,0,D9*(1-'Phí sàn theo shop'!$D$2)) -> 4.1462159 | F9: =SUMIFS('Raw Data - Nhóm SP'!$E:$E,'Raw Data - Nhóm SP'!$C:$C,"Tinh Dầu Khuếch Tán",'Raw Data - Nhóm SP'!$B:$B,"Aroma Story - The Art Of Scent",'Raw Data - Nhóm SP'!$A:$A,">="&DATE(2026,7,1),'Raw Data - Nhóm SP'!$A:$A,"<="&DATE(2026,7,7)) -> 5329350 | G9: =SUMIFS('Raw Data - Nhóm SP'!$F:$F,'Raw Data - Nhóm SP'!$C:$C,"Tinh Dầu Khuếch Tán",'Raw Data - Nhóm SP'!$B:$B,"Aroma Story - The Art Of Scent",'Raw Data - Nhóm SP'!$A:$A,">="&DATE(2026,7,1),'Raw Data - Nhóm SP'!$A:$A,"<="&DATE(2026,7,7)) -> 28523558 | H9: =IF(F9=0,0,G9/F9) -> 5.3521645 | I9: =IF(F9=0,0,H9*(1-'Phí sàn theo shop'!$D$3)) -> 3.6882242 | J9: =IF(OR(B9=0,F9=0),IF(B9=0,"Chỉ TAOS có data",IF(F9=0,"Chỉ GHT có data","-")),IF(ABS(E9-I9)/MAX(E9,I9)<0.03,"Ngang nhau -> uu tien GHT",IF(E9>I9,"Don ve GHT","Don ve TAOS"))) -> Don ve GHT
A10: Tinh Dầu 10ml (Nguyên Chất) | B10: =SUMIFS('Raw Data - Nhóm SP'!$E:$E,'Raw Data - Nhóm SP'!$C:$C,"Tinh Dầu 10ml (Nguyên Chất)",'Raw Data - Nhóm SP'!$B:$B,"Aroma Story - Góc Hương Thơm",'Raw Data - Nhóm SP'!$A:$A,">="&DATE(2026,7,1),'Raw Data - Nhóm SP'!$A:$A,"<="&DATE(2026,7,7)) -> 0 | C10: =SUMIFS('Raw Data - Nhóm SP'!$F:$F,'Raw Data - Nhóm SP'!$C:$C,"Tinh Dầu 10ml (Nguyên Chất)",'Raw Data - Nhóm SP'!$B:$B,"Aroma Story - Góc Hương Thơm",'Raw Data - Nhóm SP'!$A:$A,">="&DATE(2026,7,1),'Raw Data - Nhóm SP'!$A:$A,"<="&DATE(2026,7,7)) -> 0 | D10: =IF(B10=0,0,C10/B10) -> 0 | E10: =IF(B10=0,0,D10*(1-'Phí sàn theo shop'!$D$2)) -> 0 | F10: =SUMIFS('Raw Data - Nhóm SP'!$E:$E,'Raw Data - Nhóm SP'!$C:$C,"Tinh Dầu 10ml (Nguyên Chất)",'Raw Data - Nhóm SP'!$B:$B,"Aroma Story - The Art Of Scent",'Raw Data - Nhóm SP'!$A:$A,">="&DATE(2026,7,1),'Raw Data - Nhóm SP'!$A:$A,"<="&DATE(2026,7,7)) -> 1499031 | G10: =SUMIFS('Raw Data - Nhóm SP'!$F:$F,'Raw Data - Nhóm SP'!$C:$C,"Tinh Dầu 10ml (Nguyên Chất)",'Raw Data - Nhóm SP'!$B:$B,"Aroma Story - The Art Of Scent",'Raw Data - Nhóm SP'!$A:$A,">="&DATE(2026,7,1),'Raw Data - Nhóm SP'!$A:$A,"<="&DATE(2026,7,7)) -> 7882682 | H10: =IF(F10=0,0,G10/F10) -> 5.2585183 | I10: =IF(F10=0,0,H10*(1-'Phí sàn theo shop'!$D$3)) -> 3.6236918 | J10: =IF(OR(B10=0,F10=0),IF(B10=0,"Chỉ TAOS có data",IF(F10=0,"Chỉ GHT có data","-")),IF(ABS(E10-I10)/MAX(E10,I10)<0.03,"Ngang nhau -> uu tien GHT",IF(E10>I10,"Don ve GHT","Don ve TAOS"))) -> Chỉ TAOS có data
A11: Xịt Thơm Phòng | B11: =SUMIFS('Raw Data - Nhóm SP'!$E:$E,'Raw Data - Nhóm SP'!$C:$C,"Xịt Thơm Phòng",'Raw Data - Nhóm SP'!$B:$B,"Aroma Story - Góc Hương Thơm",'Raw Data - Nhóm SP'!$A:$A,">="&DATE(2026,7,1),'Raw Data - Nhóm SP'!$A:$A,"<="&DATE(2026,7,7)) -> 428046 | C11: =SUMIFS('Raw Data - Nhóm SP'!$F:$F,'Raw Data - Nhóm SP'!$C:$C,"Xịt Thơm Phòng",'Raw Data - Nhóm SP'!$B:$B,"Aroma Story - Góc Hương Thơm",'Raw Data - Nhóm SP'!$A:$A,">="&DATE(2026,7,1),'Raw Data - Nhóm SP'!$A:$A,"<="&DATE(2026,7,7)) -> 1888743 | D11: =IF(B11=0,0,C11/B11) -> 4.4124767 | E11: =IF(B11=0,0,D11*(1-'Phí sàn theo shop'!$D$2)) -> 3.3693047 | F11: =SUMIFS('Raw Data - Nhóm SP'!$E:$E,'Raw Data - Nhóm SP'!$C:$C,"Xịt Thơm Phòng",'Raw Data - Nhóm SP'!$B:$B,"Aroma Story - The Art Of Scent",'Raw Data - Nhóm SP'!$A:$A,">="&DATE(2026,7,1),'Raw Data - Nhóm SP'!$A:$A,"<="&DATE(2026,7,7)) -> 0 | G11: =SUMIFS('Raw Data - Nhóm SP'!$F:$F,'Raw Data - Nhóm SP'!$C:$C,"Xịt Thơm Phòng",'Raw Data - Nhóm SP'!$B:$B,"Aroma Story - The Art Of Scent",'Raw Data - Nhóm SP'!$A:$A,">="&DATE(2026,7,1),'Raw Data - Nhóm SP'!$A:$A,"<="&DATE(2026,7,7)) -> 0 | H11: =IF(F11=0,0,G11/F11) -> 0 | I11: =IF(F11=0,0,H11*(1-'Phí sàn theo shop'!$D$3)) -> 0 | J11: =IF(OR(B11=0,F11=0),IF(B11=0,"Chỉ TAOS có data",IF(F11=0,"Chỉ GHT có data","-")),IF(ABS(E11-I11)/MAX(E11,I11)<0.03,"Ngang nhau -> uu tien GHT",IF(E11>I11,"Don ve GHT","Don ve TAOS"))) -> Chỉ GHT có data
A12: Set Quà / Combo | B12: =SUMIFS('Raw Data - Nhóm SP'!$E:$E,'Raw Data - Nhóm SP'!$C:$C,"Set Quà / Combo",'Raw Data - Nhóm SP'!$B:$B,"Aroma Story - Góc Hương Thơm",'Raw Data - Nhóm SP'!$A:$A,">="&DATE(2026,7,1),'Raw Data - Nhóm SP'!$A:$A,"<="&DATE(2026,7,7)) -> 1290203 | C12: =SUMIFS('Raw Data - Nhóm SP'!$F:$F,'Raw Data - Nhóm SP'!$C:$C,"Set Quà / Combo",'Raw Data - Nhóm SP'!$B:$B,"Aroma Story - Góc Hương Thơm",'Raw Data - Nhóm SP'!$A:$A,">="&DATE(2026,7,1),'Raw Data - Nhóm SP'!$A:$A,"<="&DATE(2026,7,7)) -> 5940309 | D12: =IF(B12=0,0,C12/B12) -> 4.6041662 | E12: =IF(B12=0,0,D12*(1-'Phí sàn theo shop'!$D$2)) -> 3.5156761 | F12: =SUMIFS('Raw Data - Nhóm SP'!$E:$E,'Raw Data - Nhóm SP'!$C:$C,"Set Quà / Combo",'Raw Data - Nhóm SP'!$B:$B,"Aroma Story - The Art Of Scent",'Raw Data - Nhóm SP'!$A:$A,">="&DATE(2026,7,1),'Raw Data - Nhóm SP'!$A:$A,"<="&DATE(2026,7,7)) -> 0 | G12: =SUMIFS('Raw Data - Nhóm SP'!$F:$F,'Raw Data - Nhóm SP'!$C:$C,"Set Quà / Combo",'Raw Data - Nhóm SP'!$B:$B,"Aroma Story - The Art Of Scent",'Raw Data - Nhóm SP'!$A:$A,">="&DATE(2026,7,1),'Raw Data - Nhóm SP'!$A:$A,"<="&DATE(2026,7,7)) -> 0 | H12: =IF(F12=0,0,G12/F12) -> 0 | I12: =IF(F12=0,0,H12*(1-'Phí sàn theo shop'!$D$3)) -> 0 | J12: =IF(OR(B12=0,F12=0),IF(B12=0,"Chỉ TAOS có data",IF(F12=0,"Chỉ GHT có data","-")),IF(ABS(E12-I12)/MAX(E12,I12)<0.03,"Ngang nhau -> uu tien GHT",IF(E12>I12,"Don ve GHT","Don ve TAOS"))) -> Chỉ GHT có data
A13: TONG - TAT CA ADS (blended) | B13: =SUMIFS('Raw Data - Nhóm SP'!$E:$E,'Raw Data - Nhóm SP'!$B:$B,"Aroma Story - Góc Hương Thơm",'Raw Data - Nhóm SP'!$A:$A,">="&DATE(2026,7,1),'Raw Data - Nhóm SP'!$A:$A,"<="&DATE(2026,7,7)) -> 9263266 | C13: =SUMIFS('Raw Data - Nhóm SP'!$F:$F,'Raw Data - Nhóm SP'!$B:$B,"Aroma Story - Góc Hương Thơm",'Raw Data - Nhóm SP'!$A:$A,">="&DATE(2026,7,1),'Raw Data - Nhóm SP'!$A:$A,"<="&DATE(2026,7,7)) -> 44237874 | D13: =IF(B13=0,0,C13/B13) -> 4.7756238 | E13: =IF(B13=0,0,D13*(1-'Phí sàn theo shop'!$D$2)) -> 3.6465987 | F13: =SUMIFS('Raw Data - Nhóm SP'!$E:$E,'Raw Data - Nhóm SP'!$B:$B,"Aroma Story - The Art Of Scent",'Raw Data - Nhóm SP'!$A:$A,">="&DATE(2026,7,1),'Raw Data - Nhóm SP'!$A:$A,"<="&DATE(2026,7,7)) -> 14726738 | G13: =SUMIFS('Raw Data - Nhóm SP'!$F:$F,'Raw Data - Nhóm SP'!$B:$B,"Aroma Story - The Art Of Scent",'Raw Data - Nhóm SP'!$A:$A,">="&DATE(2026,7,1),'Raw Data - Nhóm SP'!$A:$A,"<="&DATE(2026,7,7)) -> 77542100 | H13: =IF(F13=0,0,G13/F13) -> 5.2653955 | I13: =IF(F13=0,0,H13*(1-'Phí sàn theo shop'!$D$3)) -> 3.6284309
A15: KHUNG 30 NGÀY (2026-06-08 -> 2026-07-07)
A16: Nhom san pham | B16: GOC HUONG THOM | F16: THE ART OF SCENT | J16: Khuyen nghi
B17: Chi phi | C17: Doanh so | D17: ROAS | E17: ROAS sau phi | F17: Chi phi | G17: Doanh so | H17: ROAS | I17: ROAS sau phi
A18: Nước Hoa | B18: =SUMIFS('Raw Data - Nhóm SP'!$E:$E,'Raw Data - Nhóm SP'!$C:$C,"Nước Hoa",'Raw Data - Nhóm SP'!$B:$B,"Aroma Story - Góc Hương Thơm",'Raw Data - Nhóm SP'!$A:$A,">="&DATE(2026,6,8),'Raw Data - Nhóm SP'!$A:$A,"<="&DATE(2026,7,7)) -> 4018664 | C18: =SUMIFS('Raw Data - Nhóm SP'!$F:$F,'Raw Data - Nhóm SP'!$C:$C,"Nước Hoa",'Raw Data - Nhóm SP'!$B:$B,"Aroma Story - Góc Hương Thơm",'Raw Data - Nhóm SP'!$A:$A,">="&DATE(2026,6,8),'Raw Data - Nhóm SP'!$A:$A,"<="&DATE(2026,7,7)) -> 14269230 | D18: =IF(B18=0,0,C18/B18) -> 3.5507397 | E18: =IF(B18=0,0,D18*(1-'Phí sàn theo shop'!$D$2)) -> 2.7112946 | F18: =SUMIFS('Raw Data - Nhóm SP'!$E:$E,'Raw Data - Nhóm SP'!$C:$C,"Nước Hoa",'Raw Data - Nhóm SP'!$B:$B,"Aroma Story - The Art Of Scent",'Raw Data - Nhóm SP'!$A:$A,">="&DATE(2026,6,8),'Raw Data - Nhóm SP'!$A:$A,"<="&DATE(2026,7,7)) -> 2036764 | G18: =SUMIFS('Raw Data - Nhóm SP'!$F:$F,'Raw Data - Nhóm SP'!$C:$C,"Nước Hoa",'Raw Data - Nhóm SP'!$B:$B,"Aroma Story - The Art Of Scent",'Raw Data - Nhóm SP'!$A:$A,">="&DATE(2026,6,8),'Raw Data - Nhóm SP'!$A:$A,"<="&DATE(2026,7,7)) -> 8499300 | H18: =IF(F18=0,0,G18/F18) -> 4.172943 | I18: =IF(F18=0,0,H18*(1-'Phí sàn theo shop'!$D$3)) -> 2.8756121 | J18: =IF(OR(B18=0,F18=0),IF(B18=0,"Chỉ TAOS có data",IF(F18=0,"Chỉ GHT có data","-")),IF(ABS(E18-I18)/MAX(E18,I18)<0.03,"Ngang nhau -> uu tien GHT",IF(E18>I18,"Don ve GHT","Don ve TAOS"))) -> Don ve TAOS
A19: Nến Thơm | B19: =SUMIFS('Raw Data - Nhóm SP'!$E:$E,'Raw Data - Nhóm SP'!$C:$C,"Nến Thơm",'Raw Data - Nhóm SP'!$B:$B,"Aroma Story - Góc Hương Thơm",'Raw Data - Nhóm SP'!$A:$A,">="&DATE(2026,6,8),'Raw Data - Nhóm SP'!$A:$A,"<="&DATE(2026,7,7)) -> 13626617 | C19: =SUMIFS('Raw Data - Nhóm SP'!$F:$F,'Raw Data - Nhóm SP'!$C:$C,"Nến Thơm",'Raw Data - Nhóm SP'!$B:$B,"Aroma Story - Góc Hương Thơm",'Raw Data - Nhóm SP'!$A:$A,">="&DATE(2026,6,8),'Raw Data - Nhóm SP'!$A:$A,"<="&DATE(2026,7,7)) -> 60305826 | D19: =IF(B19=0,0,C19/B19) -> 4.4255904 | E19: =IF(B19=0,0,D19*(1-'Phí sàn theo shop'!$D$2)) -> 3.3793182 | F19: =SUMIFS('Raw Data - Nhóm SP'!$E:$E,'Raw Data - Nhóm SP'!$C:$C,"Nến Thơm",'Raw Data - Nhóm SP'!$B:$B,"Aroma Story - The Art Of Scent",'Raw Data - Nhóm SP'!$A:$A,">="&DATE(2026,6,8),'Raw Data - Nhóm SP'!$A:$A,"<="&DATE(2026,7,7)) -> 35634729 | G19: =SUMIFS('Raw Data - Nhóm SP'!$F:$F,'Raw Data - Nhóm SP'!$C:$C,"Nến Thơm",'Raw Data - Nhóm SP'!$B:$B,"Aroma Story - The Art Of Scent",'Raw Data - Nhóm SP'!$A:$A,">="&DATE(2026,6,8),'Raw Data - Nhóm SP'!$A:$A,"<="&DATE(2026,7,7)) -> 185748827 | H19: =IF(F19=0,0,G19/F19) -> 5.2125786 | I19: =IF(F19=0,0,H19*(1-'Phí sàn theo shop'!$D$3)) -> 3.5920343 | J19: =IF(OR(B19=0,F19=0),IF(B19=0,"Chỉ TAOS có data",IF(F19=0,"Chỉ GHT có data","-")),IF(ABS(E19-I19)/MAX(E19,I19)<0.03,"Ngang nhau -> uu tien GHT",IF(E19>I19,"Don ve GHT","Don ve TAOS"))) -> Don ve TAOS
A20: Tinh Dầu Khuếch Tán | B20: =SUMIFS('Raw Data - Nhóm SP'!$E:$E,'Raw Data - Nhóm SP'!$C:$C,"Tinh Dầu Khuếch Tán",'Raw Data - Nhóm SP'!$B:$B,"Aroma Story - Góc Hương Thơm",'Raw Data - Nhóm SP'!$A:$A,">="&DATE(2026,6,8),'Raw Data - Nhóm SP'!$A:$A,"<="&DATE(2026,7,7)) -> 17872737 | C20: =SUMIFS('Raw Data - Nhóm SP'!$F:$F,'Raw Data - Nhóm SP'!$C:$C,"Tinh Dầu Khuếch Tán",'Raw Data - Nhóm SP'!$B:$B,"Aroma Story - Góc Hương Thơm",'Raw Data - Nhóm SP'!$A:$A,">="&DATE(2026,6,8),'Raw Data - Nhóm SP'!$A:$A,"<="&DATE(2026,7,7)) -> 90999268 | D20: =IF(B20=0,0,C20/B20) -> 5.0915127 | E20: =IF(B20=0,0,D20*(1-'Phí sàn theo shop'!$D$2)) -> 3.887807 | F20: =SUMIFS('Raw Data - Nhóm SP'!$E:$E,'Raw Data - Nhóm SP'!$C:$C,"Tinh Dầu Khuếch Tán",'Raw Data - Nhóm SP'!$B:$B,"Aroma Story - The Art Of Scent",'Raw Data - Nhóm SP'!$A:$A,">="&DATE(2026,6,8),'Raw Data - Nhóm SP'!$A:$A,"<="&DATE(2026,7,7)) -> 21682193 | G20: =SUMIFS('Raw Data - Nhóm SP'!$F:$F,'Raw Data - Nhóm SP'!$C:$C,"Tinh Dầu Khuếch Tán",'Raw Data - Nhóm SP'!$B:$B,"Aroma Story - The Art Of Scent",'Raw Data - Nhóm SP'!$A:$A,">="&DATE(2026,6,8),'Raw Data - Nhóm SP'!$A:$A,"<="&DATE(2026,7,7)) -> 114868057 | H20: =IF(F20=0,0,G20/F20) -> 5.2978062 | I20: =IF(F20=0,0,H20*(1-'Phí sàn theo shop'!$D$3)) -> 3.6507654 | J20: =IF(OR(B20=0,F20=0),IF(B20=0,"Chỉ TAOS có data",IF(F20=0,"Chỉ GHT có data","-")),IF(ABS(E20-I20)/MAX(E20,I20)<0.03,"Ngang nhau -> uu tien GHT",IF(E20>I20,"Don ve GHT","Don ve TAOS"))) -> Don ve GHT
A21: Tinh Dầu 10ml (Nguyên Chất) | B21: =SUMIFS('Raw Data - Nhóm SP'!$E:$E,'Raw Data - Nhóm SP'!$C:$C,"Tinh Dầu 10ml (Nguyên Chất)",'Raw Data - Nhóm SP'!$B:$B,"Aroma Story - Góc Hương Thơm",'Raw Data - Nhóm SP'!$A:$A,">="&DATE(2026,6,8),'Raw Data - Nhóm SP'!$A:$A,"<="&DATE(2026,7,7)) -> 565486 | C21: =SUMIFS('Raw Data - Nhóm SP'!$F:$F,'Raw Data - Nhóm SP'!$C:$C,"Tinh Dầu 10ml (Nguyên Chất)",'Raw Data - Nhóm SP'!$B:$B,"Aroma Story - Góc Hương Thơm",'Raw Data - Nhóm SP'!$A:$A,">="&DATE(2026,6,8),'Raw Data - Nhóm SP'!$A:$A,"<="&DATE(2026,7,7)) -> 683400 | D21: =IF(B21=0,0,C21/B21) -> 1.208518 | E21: =IF(B21=0,0,D21*(1-'Phí sàn theo shop'!$D$2)) -> 0.92280722 | F21: =SUMIFS('Raw Data - Nhóm SP'!$E:$E,'Raw Data - Nhóm SP'!$C:$C,"Tinh Dầu 10ml (Nguyên Chất)",'Raw Data - Nhóm SP'!$B:$B,"Aroma Story - The Art Of Scent",'Raw Data - Nhóm SP'!$A:$A,">="&DATE(2026,6,8),'Raw Data - Nhóm SP'!$A:$A,"<="&DATE(2026,7,7)) -> 4309305 | G21: =SUMIFS('Raw Data - Nhóm SP'!$F:$F,'Raw Data - Nhóm SP'!$C:$C,"Tinh Dầu 10ml (Nguyên Chất)",'Raw Data - Nhóm SP'!$B:$B,"Aroma Story - The Art Of Scent",'Raw Data - Nhóm SP'!$A:$A,">="&DATE(2026,6,8),'Raw Data - Nhóm SP'!$A:$A,"<="&DATE(2026,7,7)) -> 19659574 | H21: =IF(F21=0,0,G21/F21) -> 4.5621217 | I21: =IF(F21=0,0,H21*(1-'Phí sàn theo shop'!$D$3)) -> 3.1437987 | J21: =IF(OR(B21=0,F21=0),IF(B21=0,"Chỉ TAOS có data",IF(F21=0,"Chỉ GHT có data","-")),IF(ABS(E21-I21)/MAX(E21,I21)<0.03,"Ngang nhau -> uu tien GHT",IF(E21>I21,"Don ve GHT","Don ve TAOS"))) -> Don ve TAOS
A22: Xịt Thơm Phòng | B22: =SUMIFS('Raw Data - Nhóm SP'!$E:$E,'Raw Data - Nhóm SP'!$C:$C,"Xịt Thơm Phòng",'Raw Data - Nhóm SP'!$B:$B,"Aroma Story - Góc Hương Thơm",'Raw Data - Nhóm SP'!$A:$A,">="&DATE(2026,6,8),'Raw Data - Nhóm SP'!$A:$A,"<="&DATE(2026,7,7)) -> 1142913 | C22: =SUMIFS('Raw Data - Nhóm SP'!$F:$F,'Raw Data - Nhóm SP'!$C:$C,"Xịt Thơm Phòng",'Raw Data - Nhóm SP'!$B:$B,"Aroma Story - Góc Hương Thơm",'Raw Data - Nhóm SP'!$A:$A,">="&DATE(2026,6,8),'Raw Data - Nhóm SP'!$A:$A,"<="&DATE(2026,7,7)) -> 4681547 | D22: =IF(B22=0,0,C22/B22) -> 4.0961534 | E22: =IF(B22=0,0,D22*(1-'Phí sàn theo shop'!$D$2)) -> 3.1277647 | F22: =SUMIFS('Raw Data - Nhóm SP'!$E:$E,'Raw Data - Nhóm SP'!$C:$C,"Xịt Thơm Phòng",'Raw Data - Nhóm SP'!$B:$B,"Aroma Story - The Art Of Scent",'Raw Data - Nhóm SP'!$A:$A,">="&DATE(2026,6,8),'Raw Data - Nhóm SP'!$A:$A,"<="&DATE(2026,7,7)) -> 0 | G22: =SUMIFS('Raw Data - Nhóm SP'!$F:$F,'Raw Data - Nhóm SP'!$C:$C,"Xịt Thơm Phòng",'Raw Data - Nhóm SP'!$B:$B,"Aroma Story - The Art Of Scent",'Raw Data - Nhóm SP'!$A:$A,">="&DATE(2026,6,8),'Raw Data - Nhóm SP'!$A:$A,"<="&DATE(2026,7,7)) -> 0 | H22: =IF(F22=0,0,G22/F22) -> 0 | I22: =IF(F22=0,0,H22*(1-'Phí sàn theo shop'!$D$3)) -> 0 | J22: =IF(OR(B22=0,F22=0),IF(B22=0,"Chỉ TAOS có data",IF(F22=0,"Chỉ GHT có data","-")),IF(ABS(E22-I22)/MAX(E22,I22)<0.03,"Ngang nhau -> uu tien GHT",IF(E22>I22,"Don ve GHT","Don ve TAOS"))) -> Chỉ GHT có data
A23: Set Quà / Combo | B23: =SUMIFS('Raw Data - Nhóm SP'!$E:$E,'Raw Data - Nhóm SP'!$C:$C,"Set Quà / Combo",'Raw Data - Nhóm SP'!$B:$B,"Aroma Story - Góc Hương Thơm",'Raw Data - Nhóm SP'!$A:$A,">="&DATE(2026,6,8),'Raw Data - Nhóm SP'!$A:$A,"<="&DATE(2026,7,7)) -> 4056086 | C23: =SUMIFS('Raw Data - Nhóm SP'!$F:$F,'Raw Data - Nhóm SP'!$C:$C,"Set Quà / Combo",'Raw Data - Nhóm SP'!$B:$B,"Aroma Story - Góc Hương Thơm",'Raw Data - Nhóm SP'!$A:$A,">="&DATE(2026,6,8),'Raw Data - Nhóm SP'!$A:$A,"<="&DATE(2026,7,7)) -> 20334669 | D23: =IF(B23=0,0,C23/B23) -> 5.0133723 | E23: =IF(B23=0,0,D23*(1-'Phí sàn theo shop'!$D$2)) -> 3.82814 | F23: =SUMIFS('Raw Data - Nhóm SP'!$E:$E,'Raw Data - Nhóm SP'!$C:$C,"Set Quà / Combo",'Raw Data - Nhóm SP'!$B:$B,"Aroma Story - The Art Of Scent",'Raw Data - Nhóm SP'!$A:$A,">="&DATE(2026,6,8),'Raw Data - Nhóm SP'!$A:$A,"<="&DATE(2026,7,7)) -> 219645 | G23: =SUMIFS('Raw Data - Nhóm SP'!$F:$F,'Raw Data - Nhóm SP'!$C:$C,"Set Quà / Combo",'Raw Data - Nhóm SP'!$B:$B,"Aroma Story - The Art Of Scent",'Raw Data - Nhóm SP'!$A:$A,">="&DATE(2026,6,8),'Raw Data - Nhóm SP'!$A:$A,"<="&DATE(2026,7,7)) -> 878100 | H23: =IF(F23=0,0,G23/F23) -> 3.9978147 | I23: =IF(F23=0,0,H23*(1-'Phí sàn theo shop'!$D$3)) -> 2.7549297 | J23: =IF(OR(B23=0,F23=0),IF(B23=0,"Chỉ TAOS có data",IF(F23=0,"Chỉ GHT có data","-")),IF(ABS(E23-I23)/MAX(E23,I23)<0.03,"Ngang nhau -> uu tien GHT",IF(E23>I23,"Don ve GHT","Don ve TAOS"))) -> Don ve GHT
A24: TONG - TAT CA ADS (blended) | B24: =SUMIFS('Raw Data - Nhóm SP'!$E:$E,'Raw Data - Nhóm SP'!$B:$B,"Aroma Story - Góc Hương Thơm",'Raw Data - Nhóm SP'!$A:$A,">="&DATE(2026,6,8),'Raw Data - Nhóm SP'!$A:$A,"<="&DATE(2026,7,7)) -> 41380295 | C24: =SUMIFS('Raw Data - Nhóm SP'!$F:$F,'Raw Data - Nhóm SP'!$B:$B,"Aroma Story - Góc Hương Thơm",'Raw Data - Nhóm SP'!$A:$A,">="&DATE(2026,6,8),'Raw Data - Nhóm SP'!$A:$A,"<="&DATE(2026,7,7)) -> 191747778 | D24: =IF(B24=0,0,C24/B24) -> 4.6337944 | E24: =IF(B24=0,0,D24*(1-'Phí sàn theo shop'!$D$2)) -> 3.5382998 | F24: =SUMIFS('Raw Data - Nhóm SP'!$E:$E,'Raw Data - Nhóm SP'!$B:$B,"Aroma Story - The Art Of Scent",'Raw Data - Nhóm SP'!$A:$A,">="&DATE(2026,6,8),'Raw Data - Nhóm SP'!$A:$A,"<="&DATE(2026,7,7)) -> 63882636 | G24: =SUMIFS('Raw Data - Nhóm SP'!$F:$F,'Raw Data - Nhóm SP'!$B:$B,"Aroma Story - The Art Of Scent",'Raw Data - Nhóm SP'!$A:$A,">="&DATE(2026,6,8),'Raw Data - Nhóm SP'!$A:$A,"<="&DATE(2026,7,7)) -> 329653858 | H24: =IF(F24=0,0,G24/F24) -> 5.1603046 | I24: =IF(F24=0,0,H24*(1-'Phí sàn theo shop'!$D$3)) -> 3.5560118
A26: KHUNG 90 NGÀY (2026-04-09 -> 2026-07-07)
A27: Nhom san pham | B27: GOC HUONG THOM | F27: THE ART OF SCENT | J27: Khuyen nghi
B28: Chi phi | C28: Doanh so | D28: ROAS | E28: ROAS sau phi | F28: Chi phi | G28: Doanh so | H28: ROAS | I28: ROAS sau phi
A29: Nước Hoa | B29: =SUMIFS('Raw Data - Nhóm SP'!$E:$E,'Raw Data - Nhóm SP'!$C:$C,"Nước Hoa",'Raw Data - Nhóm SP'!$B:$B,"Aroma Story - Góc Hương Thơm",'Raw Data - Nhóm SP'!$A:$A,">="&DATE(2026,4,9),'Raw Data - Nhóm SP'!$A:$A,"<="&DATE(2026,7,7)) -> 11305490 | C29: =SUMIFS('Raw Data - Nhóm SP'!$F:$F,'Raw Data - Nhóm SP'!$C:$C,"Nước Hoa",'Raw Data - Nhóm SP'!$B:$B,"Aroma Story - Góc Hương Thơm",'Raw Data - Nhóm SP'!$A:$A,">="&DATE(2026,4,9),'Raw Data - Nhóm SP'!$A:$A,"<="&DATE(2026,7,7)) -> 48505298 | D29: =IF(B29=0,0,C29/B29) -> 4.2904198 | E29: =IF(B29=0,0,D29*(1-'Phí sàn theo shop'!$D$2)) -> 3.2761038 | F29: =SUMIFS('Raw Data - Nhóm SP'!$E:$E,'Raw Data - Nhóm SP'!$C:$C,"Nước Hoa",'Raw Data - Nhóm SP'!$B:$B,"Aroma Story - The Art Of Scent",'Raw Data - Nhóm SP'!$A:$A,">="&DATE(2026,4,9),'Raw Data - Nhóm SP'!$A:$A,"<="&DATE(2026,7,7)) -> 2384107 | G29: =SUMIFS('Raw Data - Nhóm SP'!$F:$F,'Raw Data - Nhóm SP'!$C:$C,"Nước Hoa",'Raw Data - Nhóm SP'!$B:$B,"Aroma Story - The Art Of Scent",'Raw Data - Nhóm SP'!$A:$A,">="&DATE(2026,4,9),'Raw Data - Nhóm SP'!$A:$A,"<="&DATE(2026,7,7)) -> 9308400 | H29: =IF(F29=0,0,G29/F29) -> 3.904355 | I29: =IF(F29=0,0,H29*(1-'Phí sàn theo shop'!$D$3)) -> 2.6905257 | J29: =IF(OR(B29=0,F29=0),IF(B29=0,"Chỉ TAOS có data",IF(F29=0,"Chỉ GHT có data","-")),IF(ABS(E29-I29)/MAX(E29,I29)<0.03,"Ngang nhau -> uu tien GHT",IF(E29>I29,"Don ve GHT","Don ve TAOS"))) -> Don ve GHT
A30: Nến Thơm | B30: =SUMIFS('Raw Data - Nhóm SP'!$E:$E,'Raw Data - Nhóm SP'!$C:$C,"Nến Thơm",'Raw Data - Nhóm SP'!$B:$B,"Aroma Story - Góc Hương Thơm",'Raw Data - Nhóm SP'!$A:$A,">="&DATE(2026,4,9),'Raw Data - Nhóm SP'!$A:$A,"<="&DATE(2026,7,7)) -> 41551215 | C30: =SUMIFS('Raw Data - Nhóm SP'!$F:$F,'Raw Data - Nhóm SP'!$C:$C,"Nến Thơm",'Raw Data - Nhóm SP'!$B:$B,"Aroma Story - Góc Hương Thơm",'Raw Data - Nhóm SP'!$A:$A,">="&DATE(2026,4,9),'Raw Data - Nhóm SP'!$A:$A,"<="&DATE(2026,7,7)) -> 185062406 | D30: =IF(B30=0,0,C30/B30) -> 4.4538386 | E30: =IF(B30=0,0,D30*(1-'Phí sàn theo shop'!$D$2)) -> 3.4008881 | F30: =SUMIFS('Raw Data - Nhóm SP'!$E:$E,'Raw Data - Nhóm SP'!$C:$C,"Nến Thơm",'Raw Data - Nhóm SP'!$B:$B,"Aroma Story - The Art Of Scent",'Raw Data - Nhóm SP'!$A:$A,">="&DATE(2026,4,9),'Raw Data - Nhóm SP'!$A:$A,"<="&DATE(2026,7,7)) -> 79900154 | G30: =SUMIFS('Raw Data - Nhóm SP'!$F:$F,'Raw Data - Nhóm SP'!$C:$C,"Nến Thơm",'Raw Data - Nhóm SP'!$B:$B,"Aroma Story - The Art Of Scent",'Raw Data - Nhóm SP'!$A:$A,">="&DATE(2026,4,9),'Raw Data - Nhóm SP'!$A:$A,"<="&DATE(2026,7,7)) -> 405182799 | H30: =IF(F30=0,0,G30/F30) -> 5.0711141 | I30: =IF(F30=0,0,H30*(1-'Phí sàn theo shop'!$D$3)) -> 3.4945499 | J30: =IF(OR(B30=0,F30=0),IF(B30=0,"Chỉ TAOS có data",IF(F30=0,"Chỉ GHT có data","-")),IF(ABS(E30-I30)/MAX(E30,I30)<0.03,"Ngang nhau -> uu tien GHT",IF(E30>I30,"Don ve GHT","Don ve TAOS"))) -> Ngang nhau -> uu tien GHT
A31: Tinh Dầu Khuếch Tán | B31: =SUMIFS('Raw Data - Nhóm SP'!$E:$E,'Raw Data - Nhóm SP'!$C:$C,"Tinh Dầu Khuếch Tán",'Raw Data - Nhóm SP'!$B:$B,"Aroma Story - Góc Hương Thơm",'Raw Data - Nhóm SP'!$A:$A,">="&DATE(2026,4,9),'Raw Data - Nhóm SP'!$A:$A,"<="&DATE(2026,7,7)) -> 42346979 | C31: =SUMIFS('Raw Data - Nhóm SP'!$F:$F,'Raw Data - Nhóm SP'!$C:$C,"Tinh Dầu Khuếch Tán",'Raw Data - Nhóm SP'!$B:$B,"Aroma Story - Góc Hương Thơm",'Raw Data - Nhóm SP'!$A:$A,">="&DATE(2026,4,9),'Raw Data - Nhóm SP'!$A:$A,"<="&DATE(2026,7,7)) -> 222774683 | D31: =IF(B31=0,0,C31/B31) -> 5.2606984 | E31: =IF(B31=0,0,D31*(1-'Phí sàn theo shop'!$D$2)) -> 4.0169948 | F31: =SUMIFS('Raw Data - Nhóm SP'!$E:$E,'Raw Data - Nhóm SP'!$C:$C,"Tinh Dầu Khuếch Tán",'Raw Data - Nhóm SP'!$B:$B,"Aroma Story - The Art Of Scent",'Raw Data - Nhóm SP'!$A:$A,">="&DATE(2026,4,9),'Raw Data - Nhóm SP'!$A:$A,"<="&DATE(2026,7,7)) -> 45245063 | G31: =SUMIFS('Raw Data - Nhóm SP'!$F:$F,'Raw Data - Nhóm SP'!$C:$C,"Tinh Dầu Khuếch Tán",'Raw Data - Nhóm SP'!$B:$B,"Aroma Story - The Art Of Scent",'Raw Data - Nhóm SP'!$A:$A,">="&DATE(2026,4,9),'Raw Data - Nhóm SP'!$A:$A,"<="&DATE(2026,7,7)) -> 241342967 | H31: =IF(F31=0,0,G31/F31) -> 5.3341282 | I31: =IF(F31=0,0,H31*(1-'Phí sàn theo shop'!$D$3)) -> 3.6757952 | J31: =IF(OR(B31=0,F31=0),IF(B31=0,"Chỉ TAOS có data",IF(F31=0,"Chỉ GHT có data","-")),IF(ABS(E31-I31)/MAX(E31,I31)<0.03,"Ngang nhau -> uu tien GHT",IF(E31>I31,"Don ve GHT","Don ve TAOS"))) -> Don ve GHT
A32: Tinh Dầu 10ml (Nguyên Chất) | B32: =SUMIFS('Raw Data - Nhóm SP'!$E:$E,'Raw Data - Nhóm SP'!$C:$C,"Tinh Dầu 10ml (Nguyên Chất)",'Raw Data - Nhóm SP'!$B:$B,"Aroma Story - Góc Hương Thơm",'Raw Data - Nhóm SP'!$A:$A,">="&DATE(2026,4,9),'Raw Data - Nhóm SP'!$A:$A,"<="&DATE(2026,7,7)) -> 1556750 | C32: =SUMIFS('Raw Data - Nhóm SP'!$F:$F,'Raw Data - Nhóm SP'!$C:$C,"Tinh Dầu 10ml (Nguyên Chất)",'Raw Data - Nhóm SP'!$B:$B,"Aroma Story - Góc Hương Thơm",'Raw Data - Nhóm SP'!$A:$A,">="&DATE(2026,4,9),'Raw Data - Nhóm SP'!$A:$A,"<="&DATE(2026,7,7)) -> 4312632 | D32: =IF(B32=0,0,C32/B32) -> 2.7702791 | E32: =IF(B32=0,0,D32*(1-'Phí sàn theo shop'!$D$2)) -> 2.1153459 | F32: =SUMIFS('Raw Data - Nhóm SP'!$E:$E,'Raw Data - Nhóm SP'!$C:$C,"Tinh Dầu 10ml (Nguyên Chất)",'Raw Data - Nhóm SP'!$B:$B,"Aroma Story - The Art Of Scent",'Raw Data - Nhóm SP'!$A:$A,">="&DATE(2026,4,9),'Raw Data - Nhóm SP'!$A:$A,"<="&DATE(2026,7,7)) -> 10490274 | G32: =SUMIFS('Raw Data - Nhóm SP'!$F:$F,'Raw Data - Nhóm SP'!$C:$C,"Tinh Dầu 10ml (Nguyên Chất)",'Raw Data - Nhóm SP'!$B:$B,"Aroma Story - The Art Of Scent",'Raw Data - Nhóm SP'!$A:$A,">="&DATE(2026,4,9),'Raw Data - Nhóm SP'!$A:$A,"<="&DATE(2026,7,7)) -> 48476426 | H32: =IF(F32=0,0,G32/F32) -> 4.6210829 | I32: =IF(F32=0,0,H32*(1-'Phí sàn theo shop'!$D$3)) -> 3.1844294 | J32: =IF(OR(B32=0,F32=0),IF(B32=0,"Chỉ TAOS có data",IF(F32=0,"Chỉ GHT có data","-")),IF(ABS(E32-I32)/MAX(E32,I32)<0.03,"Ngang nhau -> uu tien GHT",IF(E32>I32,"Don ve GHT","Don ve TAOS"))) -> Don ve TAOS
A33: Xịt Thơm Phòng | B33: =SUMIFS('Raw Data - Nhóm SP'!$E:$E,'Raw Data - Nhóm SP'!$C:$C,"Xịt Thơm Phòng",'Raw Data - Nhóm SP'!$B:$B,"Aroma Story - Góc Hương Thơm",'Raw Data - Nhóm SP'!$A:$A,">="&DATE(2026,4,9),'Raw Data - Nhóm SP'!$A:$A,"<="&DATE(2026,7,7)) -> 3340153 | C33: =SUMIFS('Raw Data - Nhóm SP'!$F:$F,'Raw Data - Nhóm SP'!$C:$C,"Xịt Thơm Phòng",'Raw Data - Nhóm SP'!$B:$B,"Aroma Story - Góc Hương Thơm",'Raw Data - Nhóm SP'!$A:$A,">="&DATE(2026,4,9),'Raw Data - Nhóm SP'!$A:$A,"<="&DATE(2026,7,7)) -> 11619533 | D33: =IF(B33=0,0,C33/B33) -> 3.4787427 | E33: =IF(B33=0,0,D33*(1-'Phí sàn theo shop'!$D$2)) -> 2.6563187 | F33: =SUMIFS('Raw Data - Nhóm SP'!$E:$E,'Raw Data - Nhóm SP'!$C:$C,"Xịt Thơm Phòng",'Raw Data - Nhóm SP'!$B:$B,"Aroma Story - The Art Of Scent",'Raw Data - Nhóm SP'!$A:$A,">="&DATE(2026,4,9),'Raw Data - Nhóm SP'!$A:$A,"<="&DATE(2026,7,7)) -> 207270 | G33: =SUMIFS('Raw Data - Nhóm SP'!$F:$F,'Raw Data - Nhóm SP'!$C:$C,"Xịt Thơm Phòng",'Raw Data - Nhóm SP'!$B:$B,"Aroma Story - The Art Of Scent",'Raw Data - Nhóm SP'!$A:$A,">="&DATE(2026,4,9),'Raw Data - Nhóm SP'!$A:$A,"<="&DATE(2026,7,7)) -> 446200 | H33: =IF(F33=0,0,G33/F33) -> 2.1527476 | I33: =IF(F33=0,0,H33*(1-'Phí sàn theo shop'!$D$3)) -> 1.4834775 | J33: =IF(OR(B33=0,F33=0),IF(B33=0,"Chỉ TAOS có data",IF(F33=0,"Chỉ GHT có data","-")),IF(ABS(E33-I33)/MAX(E33,I33)<0.03,"Ngang nhau -> uu tien GHT",IF(E33>I33,"Don ve GHT","Don ve TAOS"))) -> Don ve GHT
A34: Set Quà / Combo | B34: =SUMIFS('Raw Data - Nhóm SP'!$E:$E,'Raw Data - Nhóm SP'!$C:$C,"Set Quà / Combo",'Raw Data - Nhóm SP'!$B:$B,"Aroma Story - Góc Hương Thơm",'Raw Data - Nhóm SP'!$A:$A,">="&DATE(2026,4,9),'Raw Data - Nhóm SP'!$A:$A,"<="&DATE(2026,7,7)) -> 16528621 | C34: =SUMIFS('Raw Data - Nhóm SP'!$F:$F,'Raw Data - Nhóm SP'!$C:$C,"Set Quà / Combo",'Raw Data - Nhóm SP'!$B:$B,"Aroma Story - Góc Hương Thơm",'Raw Data - Nhóm SP'!$A:$A,">="&DATE(2026,4,9),'Raw Data - Nhóm SP'!$A:$A,"<="&DATE(2026,7,7)) -> 78483530 | D34: =IF(B34=0,0,C34/B34) -> 4.7483411 | E34: =IF(B34=0,0,D34*(1-'Phí sàn theo shop'!$D$2)) -> 3.625766 | F34: =SUMIFS('Raw Data - Nhóm SP'!$E:$E,'Raw Data - Nhóm SP'!$C:$C,"Set Quà / Combo",'Raw Data - Nhóm SP'!$B:$B,"Aroma Story - The Art Of Scent",'Raw Data - Nhóm SP'!$A:$A,">="&DATE(2026,4,9),'Raw Data - Nhóm SP'!$A:$A,"<="&DATE(2026,7,7)) -> 10934239 | G34: =SUMIFS('Raw Data - Nhóm SP'!$F:$F,'Raw Data - Nhóm SP'!$C:$C,"Set Quà / Combo",'Raw Data - Nhóm SP'!$B:$B,"Aroma Story - The Art Of Scent",'Raw Data - Nhóm SP'!$A:$A,">="&DATE(2026,4,9),'Raw Data - Nhóm SP'!$A:$A,"<="&DATE(2026,7,7)) -> 57430891 | H34: =IF(F34=0,0,G34/F34) -> 5.2523903 | I34: =IF(F34=0,0,H34*(1-'Phí sàn theo shop'!$D$3)) -> 3.6194689 | J34: =IF(OR(B34=0,F34=0),IF(B34=0,"Chỉ TAOS có data",IF(F34=0,"Chỉ GHT có data","-")),IF(ABS(E34-I34)/MAX(E34,I34)<0.03,"Ngang nhau -> uu tien GHT",IF(E34>I34,"Don ve GHT","Don ve TAOS"))) -> Ngang nhau -> uu tien GHT
A35: TONG - TAT CA ADS (blended) | B35: =SUMIFS('Raw Data - Nhóm SP'!$E:$E,'Raw Data - Nhóm SP'!$B:$B,"Aroma Story - Góc Hương Thơm",'Raw Data - Nhóm SP'!$A:$A,">="&DATE(2026,4,9),'Raw Data - Nhóm SP'!$A:$A,"<="&DATE(2026,7,7)) -> 118172085 | C35: =SUMIFS('Raw Data - Nhóm SP'!$F:$F,'Raw Data - Nhóm SP'!$B:$B,"Aroma Story - Góc Hương Thơm",'Raw Data - Nhóm SP'!$A:$A,">="&DATE(2026,4,9),'Raw Data - Nhóm SP'!$A:$A,"<="&DATE(2026,7,7)) -> 556092979 | D35: =IF(B35=0,0,C35/B35) -> 4.7057897 | E35: =IF(B35=0,0,D35*(1-'Phí sàn theo shop'!$D$2)) -> 3.5932744 | F35: =SUMIFS('Raw Data - Nhóm SP'!$E:$E,'Raw Data - Nhóm SP'!$B:$B,"Aroma Story - The Art Of Scent",'Raw Data - Nhóm SP'!$A:$A,">="&DATE(2026,4,9),'Raw Data - Nhóm SP'!$A:$A,"<="&DATE(2026,7,7)) -> 152485933 | G35: =SUMIFS('Raw Data - Nhóm SP'!$F:$F,'Raw Data - Nhóm SP'!$B:$B,"Aroma Story - The Art Of Scent",'Raw Data - Nhóm SP'!$A:$A,">="&DATE(2026,4,9),'Raw Data - Nhóm SP'!$A:$A,"<="&DATE(2026,7,7)) -> 770597113 | H35: =IF(F35=0,0,G35/F35) -> 5.053562 | I35: =IF(F35=0,0,H35*(1-'Phí sàn theo shop'!$D$3)) -> 3.4824545

Sheet Theo san pham (7-30-90d)
A1: Ads Shopee theo SAN PHAM CHI TIET (ghep cap ten gan giong nhau giua 2 shop) - 3 khung thoi gian
A2: Chi gom campaign quang cao 1 SAN PHAM CU THE (co Ma san pham) - khong gom campaign dang bo suu tap nhieu san pham. Ten san pham o 2 shop duoc ghep cap theo do giong ten (khong phai trung tuyet doi) - TU KIEM TRA lai sheet 'Ghi chu ghep SP' neu thay ten 2 ben khac xa nhau. San pham chi chay o 1 shop thi cot shop kia hien 0/-. Dong TONG = ROAS blended TOAN BO ads (ke ca campaign bo suu tap), khong chi tong cac san pham ben duoi.
A4: KHUNG 7 NGÀY (2026-07-01 -> 2026-07-07)
A5: San pham | B5: GOC HUONG THOM | F5: THE ART OF SCENT | J5: Khuyen nghi
B6: Chi phi | C6: Doanh so | D6: ROAS | E6: ROAS sau phi | F6: Chi phi | G6: Doanh so | H6: ROAS | I6: ROAS sau phi
A7: Bộ Sản Phẩm Tinh Dầu Cà Phê & Lọ Tán Hương Aroma Story – Hương Thơm Tự Nhiên, Giúp Tập Trung & Thư Giãn | B7: =SUMIFS('Raw Data - Sản phẩm'!$F:$F,'Raw Data - Sản phẩm'!$D:$D,"Bộ Sản Phẩm Tinh Dầu Cà Phê & Lọ Tán Hương Aroma Story – Hương Thơm Tự Nhiên, Giúp Tập Trung & Thư Giãn",'Raw Data - Sản phẩm'!$B:$B,"Aroma Story - Góc Hương Thơm",'Raw Data - Sản phẩm'!$A:$A,">="&DATE(2026,7,1),'Raw Data - Sản phẩm'!$A:$A,"<="&DATE(2026,7,7)) -> 0 | C7: =SUMIFS('Raw Data - Sản phẩm'!$G:$G,'Raw Data - Sản phẩm'!$D:$D,"Bộ Sản Phẩm Tinh Dầu Cà Phê & Lọ Tán Hương Aroma Story – Hương Thơm Tự Nhiên, Giúp Tập Trung & Thư Giãn",'Raw Data - Sản phẩm'!$B:$B,"Aroma Story - Góc Hương Thơm",'Raw Data - Sản phẩm'!$A:$A,">="&DATE(2026,7,1),'Raw Data - Sản phẩm'!$A:$A,"<="&DATE(2026,7,7)) -> 0 | D7: =IF(B7=0,0,C7/B7) -> 0 | E7: =IF(B7=0,0,D7*(1-'Phí sàn theo shop'!$D$2)) -> 0 | F7: =SUMIFS('Raw Data - Sản phẩm'!$F:$F,'Raw Data - Sản phẩm'!$D:$D,"Bộ Sản Phẩm Tinh Dầu Cà Phê & Lọ Tán Hương Aroma Story – Hương Thơm Tự Nhiên, Giúp Tập Trung & Thư Giãn",'Raw Data - Sản phẩm'!$B:$B,"Aroma Story - The Art Of Scent",'Raw Data - Sản phẩm'!$A:$A,">="&DATE(2026,7,1),'Raw Data - Sản phẩm'!$A:$A,"<="&DATE(2026,7,7)) -> 0 | G7: =SUMIFS('Raw Data - Sản phẩm'!$G:$G,'Raw Data - Sản phẩm'!$D:$D,"Bộ Sản Phẩm Tinh Dầu Cà Phê & Lọ Tán Hương Aroma Story – Hương Thơm Tự Nhiên, Giúp Tập Trung & Thư Giãn",'Raw Data - Sản phẩm'!$B:$B,"Aroma Story - The Art Of Scent",'Raw Data - Sản phẩm'!$A:$A,">="&DATE(2026,7,1),'Raw Data - Sản phẩm'!$A:$A,"<="&DATE(2026,7,7)) -> 0 | H7: =IF(F7=0,0,G7/F7) -> 0 | I7: =IF(F7=0,0,H7*(1-'Phí sàn theo shop'!$D$3)) -> 0 | J7: =IF(OR(B7=0,F7=0),IF(B7=0,"Chỉ TAOS có data",IF(F7=0,"Chỉ GHT có data","-")),IF(ABS(E7-I7)/MAX(E7,I7)<0.03,"Ngang nhau -> uu tien GHT",IF(E7>I7,"Don ve GHT","Don ve TAOS"))) -> Chỉ TAOS có data
A8: BST Nước Hoa Nam Aroma Story EDP 30ml – Hương Thơm Nam Tính, Cuốn Hút | B8: =SUMIFS('Raw Data - Sản phẩm'!$F:$F,'Raw Data - Sản phẩm'!$D:$D,"BST Nước Hoa Nam Aroma Story EDP 30ml – Hương Thơm Nam Tính, Cuốn Hút",'Raw Data - Sản phẩm'!$B:$B,"Aroma Story - Góc Hương Thơm",'Raw Data - Sản phẩm'!$A:$A,">="&DATE(2026,7,1),'Raw Data - Sản phẩm'!$A:$A,"<="&DATE(2026,7,7)) -> 0 | C8: =SUMIFS('Raw Data - Sản phẩm'!$G:$G,'Raw Data - Sản phẩm'!$D:$D,"BST Nước Hoa Nam Aroma Story EDP 30ml – Hương Thơm Nam Tính, Cuốn Hút",'Raw Data - Sản phẩm'!$B:$B,"Aroma Story - Góc Hương Thơm",'Raw Data - Sản phẩm'!$A:$A,">="&DATE(2026,7,1),'Raw Data - Sản phẩm'!$A:$A,"<="&DATE(2026,7,7)) -> 0 | D8: =IF(B8=0,0,C8/B8) -> 0 | E8: =IF(B8=0,0,D8*(1-'Phí sàn theo shop'!$D$2)) -> 0 | F8: =SUMIFS('Raw Data - Sản phẩm'!$F:$F,'Raw Data - Sản phẩm'!$D:$D,"BST Nước Hoa Nam Aroma Story EDP 30ml – Hương Thơm Nam Tính, Cuốn Hút",'Raw Data - Sản phẩm'!$B:$B,"Aroma Story - The Art Of Scent",'Raw Data - Sản phẩm'!$A:$A,">="&DATE(2026,7,1),'Raw Data - Sản phẩm'!$A:$A,"<="&DATE(2026,7,7)) -> 0 | G8: =SUMIFS('Raw Data - Sản phẩm'!$G:$G,'Raw Data - Sản phẩm'!$D:$D,"BST Nước Hoa Nam Aroma Story EDP 30ml – Hương Thơm Nam Tính, Cuốn Hút",'Raw Data - Sản phẩm'!$B:$B,"Aroma Story - The Art Of Scent",'Raw Data - Sản phẩm'!$A:$A,">="&DATE(2026,7,1),'Raw Data - Sản phẩm'!$A:$A,"<="&DATE(2026,7,7)) -> 0 | H8: =IF(F8=0,0,G8/F8) -> 0 | I8: =IF(F8=0,0,H8*(1-'Phí sàn theo shop'!$D$3)) -> 0 | J8: =IF(OR(B8=0,F8=0),IF(B8=0,"Chỉ TAOS có data",IF(F8=0,"Chỉ GHT có data","-")),IF(ABS(E8-I8)/MAX(E8,I8)<0.03,"Ngang nhau -> uu tien GHT",IF(E8>I8,"Don ve GHT","Don ve TAOS"))) -> Chỉ TAOS có data
A9: BST Nước Hoa Nữ Aroma Story EDP 30ml – Hương Thơm, Nữ Tính, Thanh Lịch | B9: =SUMIFS('Raw Data - Sản phẩm'!$F:$F,'Raw Data - Sản phẩm'!$D:$D,"BST Nước Hoa Nữ Aroma Story EDP 30ml – Hương Thơm, Nữ Tính, Thanh Lịch",'Raw Data - Sản phẩm'!$B:$B,"Aroma Story - Góc Hương Thơm",'Raw Data - Sản phẩm'!$A:$A,">="&DATE(2026,7,1),'Raw Data - Sản phẩm'!$A:$A,"<="&DATE(2026,7,7)) -> 0 | C9: =SUMIFS('Raw Data - Sản phẩm'!$G:$G,'Raw Data - Sản phẩm'!$D:$D,"BST Nước Hoa Nữ Aroma Story EDP 30ml – Hương Thơm, Nữ Tính, Thanh Lịch",'Raw Data - Sản phẩm'!$B:$B,"Aroma Story - Góc Hương Thơm",'Raw Data - Sản phẩm'!$A:$A,">="&DATE(2026,7,1),'Raw Data - Sản phẩm'!$A:$A,"<="&DATE(2026,7,7)) -> 0 | D9: =IF(B9=0,0,C9/B9) -> 0 | E9: =IF(B9=0,0,D9*(1-'Phí sàn theo shop'!$D$2)) -> 0 | F9: =SUMIFS('Raw Data - Sản phẩm'!$F:$F,'Raw Data - Sản phẩm'!$D:$D,"BST Nước Hoa Nữ Aroma Story EDP 30ml – Hương Thơm, Nữ Tính, Thanh Lịch",'Raw Data - Sản phẩm'!$B:$B,"Aroma Story - The Art Of Scent",'Raw Data - Sản phẩm'!$A:$A,">="&DATE(2026,7,1),'Raw Data - Sản phẩm'!$A:$A,"<="&DATE(2026,7,7)) -> 0 | G9: =SUMIFS('Raw Data - Sản phẩm'!$G:$G,'Raw Data - Sản phẩm'!$D:$D,"BST Nước Hoa Nữ Aroma Story EDP 30ml – Hương Thơm, Nữ Tính, Thanh Lịch",'Raw Data - Sản phẩm'!$B:$B,"Aroma Story - The Art Of Scent",'Raw Data - Sản phẩm'!$A:$A,">="&DATE(2026,7,1),'Raw Data - Sản phẩm'!$A:$A,"<="&DATE(2026,7,7)) -> 0 | H9: =IF(F9=0,0,G9/F9) -> 0 | I9: =IF(F9=0,0,H9*(1-'Phí sàn theo shop'!$D$3)) -> 0 | J9: =IF(OR(B9=0,F9=0),IF(B9=0,"Chỉ TAOS có data",IF(F9=0,"Chỉ GHT có data","-")),IF(ABS(E9-I9)/MAX(E9,I9)<0.03,"Ngang nhau -> uu tien GHT",IF(E9>I9,"Don ve GHT","Don ve TAOS"))) -> Chỉ TAOS có data
A10: Nước Hoa Nữ Very Good Girl Aroma Story EDP 30ml – Hương Hoa Ngọt Ngào, Quyến Rũ | B10: =SUMIFS('Raw Data - Sản phẩm'!$F:$F,'Raw Data - Sản phẩm'!$D:$D,"Nước Hoa Nữ Very Good Girl Aroma Story EDP 30ml – Hương Hoa Ngọt Ngào, Quyến Rũ",'Raw Data - Sản phẩm'!$B:$B,"Aroma Story - Góc Hương Thơm",'Raw Data - Sản phẩm'!$A:$A,">="&DATE(2026,7,1),'Raw Data - Sản phẩm'!$A:$A,"<="&DATE(2026,7,7)) -> 0 | C10: =SUMIFS('Raw Data - Sản phẩm'!$G:$G,'Raw Data - Sản phẩm'!$D:$D,"Nước Hoa Nữ Very Good Girl Aroma Story EDP 30ml – Hương Hoa Ngọt Ngào, Quyến Rũ",'Raw Data - Sản phẩm'!$B:$B,"Aroma Story - Góc Hương Thơm",'Raw Data - Sản phẩm'!$A:$A,">="&DATE(2026,7,1),'Raw Data - Sản phẩm'!$A:$A,"<="&DATE(2026,7,7)) -> 0 | D10: =IF(B10=0,0,C10/B10) -> 0 | E10: =IF(B10=0,0,D10*(1-'Phí sàn theo shop'!$D$2)) -> 0 | F10: =SUMIFS('Raw Data - Sản phẩm'!$F:$F,'Raw Data - Sản phẩm'!$D:$D,"Nước Hoa Nữ Very Good Girl Aroma Story EDP 30ml – Hương Hoa Ngọt Ngào, Quyến Rũ",'Raw Data - Sản phẩm'!$B:$B,"Aroma Story - The Art Of Scent",'Raw Data - Sản phẩm'!$A:$A,">="&DATE(2026,7,1),'Raw Data - Sản phẩm'!$A:$A,"<="&DATE(2026,7,7)) -> 0 | G10: =SUMIFS('Raw Data - Sản phẩm'!$G:$G,'Raw Data - Sản phẩm'!$D:$D,"Nước Hoa Nữ Very Good Girl Aroma Story EDP 30ml – Hương Hoa Ngọt Ngào, Quyến Rũ",'Raw Data - Sản phẩm'!$B:$B,"Aroma Story - The Art Of Scent",'Raw Data - Sản phẩm'!$A:$A,">="&DATE(2026,7,1),'Raw Data - Sản phẩm'!$A:$A,"<="&DATE(2026,7,7)) -> 0 | H10: =IF(F10=0,0,G10/F10) -> 0 | I10: =IF(F10=0,0,H10*(1-'Phí sàn theo shop'!$D$3)) -> 0 | J10: =IF(OR(B10=0,F10=0),IF(B10=0,"Chỉ TAOS có data",IF(F10=0,"Chỉ GHT có data","-")),IF(ABS(E10-I10)/MAX(E10,I10)<0.03,"Ngang nhau -> uu tien GHT",IF(E10>I10,"Don ve GHT","Don ve TAOS"))) -> Chỉ TAOS có data
A11: Nước Hoa Tóc Aroma Story Giúp Thơm Mượt Tóc, Tránh Bết, Khử Mùi, Size 10ml/100ml | B11: =SUMIFS('Raw Data - Sản phẩm'!$F:$F,'Raw Data - Sản phẩm'!$D:$D,"Nước Hoa Tóc Aroma Story Giúp Thơm Mượt Tóc, Tránh Bết, Khử Mùi, Size 10ml/100ml",'Raw Data - Sản phẩm'!$B:$B,"Aroma Story - Góc Hương Thơm",'Raw Data - Sản phẩm'!$A:$A,">="&DATE(2026,7,1),'Raw Data - Sản phẩm'!$A:$A,"<="&DATE(2026,7,7)) -> 40288 | C11: =SUMIFS('Raw Data - Sản phẩm'!$G:$G,'Raw Data - Sản phẩm'!$D:$D,"Nước Hoa Tóc Aroma Story Giúp Thơm Mượt Tóc, Tránh Bết, Khử Mùi, Size 10ml/100ml",'Raw Data - Sản phẩm'!$B:$B,"Aroma Story - Góc Hương Thơm",'Raw Data - Sản phẩm'!$A:$A,">="&DATE(2026,7,1),'Raw Data - Sản phẩm'!$A:$A,"<="&DATE(2026,7,7)) -> 195000 | D11: =IF(B11=0,0,C11/B11) -> 4.8401509 | E11: =IF(B11=0,0,D11*(1-'Phí sàn theo shop'!$D$2)) -> 3.6958707 | F11: =SUMIFS('Raw Data - Sản phẩm'!$F:$F,'Raw Data - Sản phẩm'!$D:$D,"Nước Hoa Tóc Aroma Story Giúp Thơm Mượt Tóc, Tránh Bết, Khử Mùi, Size 10ml/100ml",'Raw Data - Sản phẩm'!$B:$B,"Aroma Story - The Art Of Scent",'Raw Data - Sản phẩm'!$A:$A,">="&DATE(2026,7,1),'Raw Data - Sản phẩm'!$A:$A,"<="&DATE(2026,7,7)) -> 0 | G11: =SUMIFS('Raw Data - Sản phẩm'!$G:$G,'Raw Data - Sản phẩm'!$D:$D,"Nước Hoa Tóc Aroma Story Giúp Thơm Mượt Tóc, Tránh Bết, Khử Mùi, Size 10ml/100ml",'Raw Data - Sản phẩm'!$B:$B,"Aroma Story - The Art Of Scent",'Raw Data - Sản phẩm'!$A:$A,">="&DATE(2026,7,1),'Raw Data - Sản phẩm'!$A:$A,"<="&DATE(2026,7,7)) -> 0 | H11: =IF(F11=0,0,G11/F11) -> 0 | I11: =IF(F11=0,0,H11*(1-'Phí sàn theo shop'!$D$3)) -> 0 | J11: =IF(OR(B11=0,F11=0),IF(B11=0,"Chỉ TAOS có data",IF(F11=0,"Chỉ GHT có data","-")),IF(ABS(E11-I11)/MAX(E11,I11)<0.03,"Ngang nhau -> uu tien GHT",IF(E11>I11,"Don ve GHT","Don ve TAOS"))) -> Chỉ GHT có data
A12: Xịt Thơm Phòng, Quấn Áo Trà Trắng & Sung Aroma Story, Nước Hoa Xịt Thơm Size 200ml | B12: =SUMIFS('Raw Data - Sản phẩm'!$F:$F,'Raw Data - Sản phẩm'!$D:$D,"Xịt Thơm Phòng, Quấn Áo Trà Trắng & Sung Aroma Story, Nước Hoa Xịt Thơm Size 200ml",'Raw Data - Sản phẩm'!$B:$B,"Aroma Story - Góc Hương Thơm",'Raw Data - Sản phẩm'!$A:$A,">="&DATE(2026,7,1),'Raw Data - Sản phẩm'!$A:$A,"<="&DATE(2026,7,7)) -> 393231 | C12: =SUMIFS('Raw Data - Sản phẩm'!$G:$G,'Raw Data - Sản phẩm'!$D:$D,"Xịt Thơm Phòng, Quấn Áo Trà Trắng & Sung Aroma Story, Nước Hoa Xịt Thơm Size 200ml",'Raw Data - Sản phẩm'!$B:$B,"Aroma Story - Góc Hương Thơm",'Raw Data - Sản phẩm'!$A:$A,">="&DATE(2026,7,1),'Raw Data - Sản phẩm'!$A:$A,"<="&DATE(2026,7,7)) -> 1772757 | D12: =IF(B12=0,0,C12/B12) -> 4.5081822 | E12: =IF(B12=0,0,D12*(1-'Phí sàn theo shop'!$D$2)) -> 3.4423841 | F12: =SUMIFS('Raw Data - Sản phẩm'!$F:$F,'Raw Data - Sản phẩm'!$D:$D,"Xịt Thơm Phòng, Quấn Áo Trà Trắng & Sung Aroma Story, Nước Hoa Xịt Thơm Size 200ml",'Raw Data - Sản phẩm'!$B:$B,"Aroma Story - The Art Of Scent",'Raw Data - Sản phẩm'!$A:$A,">="&DATE(2026,7,1),'Raw Data - Sản phẩm'!$A:$A,"<="&DATE(2026,7,7)) -> 0 | G12: =SUMIFS('Raw Data - Sản phẩm'!$G:$G,'Raw Data - Sản phẩm'!$D:$D,"Xịt Thơm Phòng, Quấn Áo Trà Trắng & Sung Aroma Story, Nước Hoa Xịt Thơm Size 200ml",'Raw Data - Sản phẩm'!$B:$B,"Aroma Story - The Art Of Scent",'Raw Data - Sản phẩm'!$A:$A,">="&DATE(2026,7,1),'Raw Data - Sản phẩm'!$A:$A,"<="&DATE(2026,7,7)) -> 0 | H12: =IF(F12=0,0,G12/F12) -> 0 | I12: =IF(F12=0,0,H12*(1-'Phí sàn theo shop'!$D$3)) -> 0 | J12: =IF(OR(B12=0,F12=0),IF(B12=0,"Chỉ TAOS có data",IF(F12=0,"Chỉ GHT có data","-")),IF(ABS(E12-I12)/MAX(E12,I12)<0.03,"Ngang nhau -> uu tien GHT",IF(E12>I12,"Don ve GHT","Don ve TAOS"))) -> Chỉ GHT có data
A13: Combo Quà Tặng Nến Thơm Aroma Story Tặng Người Yêu, Bạn Bè Dịp Sinh Nhật, Kỷ Niệm | B13: =SUMIFS('Raw Data - Sản phẩm'!$F:$F,'Raw Data - Sản phẩm'!$D:$D,"Combo Quà Tặng Nến Thơm Aroma Story Tặng Người Yêu, Bạn Bè Dịp Sinh Nhật, Kỷ Niệm",'Raw Data - Sản phẩm'!$B:$B,"Aroma Story - Góc Hương Thơm",'Raw Data - Sản phẩm'!$A:$A,">="&DATE(2026,7,1),'Raw Data - Sản phẩm'!$A:$A,"<="&DATE(2026,7,7)) -> 0 | C13: =SUMIFS('Raw Data - Sản phẩm'!$G:$G,'Raw Data - Sản phẩm'!$D:$D,"Combo Quà Tặng Nến Thơm Aroma Story Tặng Người Yêu, Bạn Bè Dịp Sinh Nhật, Kỷ Niệm",'Raw Data - Sản phẩm'!$B:$B,"Aroma Story - Góc Hương Thơm",'Raw Data - Sản phẩm'!$A:$A,">="&DATE(2026,7,1),'Raw Data - Sản phẩm'!$A:$A,"<="&DATE(2026,7,7)) -> 0 | D13: =IF(B13=0,0,C13/B13) -> 0 | E13: =IF(B13=0,0,D13*(1-'Phí sàn theo shop'!$D$2)) -> 0 | F13: =SUMIFS('Raw Data - Sản phẩm'!$F:$F,'Raw Data - Sản phẩm'!$D:$D,"Combo Quà Tặng Nến Thơm Aroma Story Tặng Người Yêu, Bạn Bè Dịp Sinh Nhật, Kỷ Niệm",'Raw Data - Sản phẩm'!$B:$B,"Aroma Story - The Art Of Scent",'Raw Data - Sản phẩm'!$A:$A,">="&DATE(2026,7,1),'Raw Data - Sản phẩm'!$A:$A,"<="&DATE(2026,7,7)) -> 0 | G13: =SUMIFS('Raw Data - Sản phẩm'!$G:$G,'Raw Data - Sản phẩm'!$D:$D,"Combo Quà Tặng Nến Thơm Aroma Story Tặng Người Yêu, Bạn Bè Dịp Sinh Nhật, Kỷ Niệm",'Raw Data - Sản phẩm'!$B:$B,"Aroma Story - The Art Of Scent",'Raw Data - Sản phẩm'!$A:$A,">="&DATE(2026,7,1),'Raw Data - Sản phẩm'!$A:$A,"<="&DATE(2026,7,7)) -> 0 | H13: =IF(F13=0,0,G13/F13) -> 0 | I13: =IF(F13=0,0,H13*(1-'Phí sàn theo shop'!$D$3)) -> 0 | J13: =IF(OR(B13=0,F13=0),IF(B13=0,"Chỉ TAOS có data",IF(F13=0,"Chỉ GHT có data","-")),IF(ABS(E13-I13)/MAX(E13,I13)<0.03,"Ngang nhau -> uu tien GHT",IF(E13>I13,"Don ve GHT","Don ve TAOS"))) -> Chỉ TAOS có data
A14: Nến Thơm Cao Cấp Aroma Story Nhiều Hương Cốc Gốm Sứ, Xi Măng, Thủy Tinh Size 100g - 250g | B14: =SUMIFS('Raw Data - Sản phẩm'!$F:$F,'Raw Data - Sản phẩm'!$D:$D,"Nến Thơm Cao Cấp Aroma Story Nhiều Hương Cốc Gốm Sứ, Xi Măng, Thủy Tinh Size 100g - 250g",'Raw Data - Sản phẩm'!$B:$B,"Aroma Story - Góc Hương Thơm",'Raw Data - Sản phẩm'!$A:$A,">="&DATE(2026,7,1),'Raw Data - Sản phẩm'!$A:$A,"<="&DATE(2026,7,7)) -> 0 | C14: =SUMIFS('Raw Data - Sản phẩm'!$G:$G,'Raw Data - Sản phẩm'!$D:$D,"Nến Thơm Cao Cấp Aroma Story Nhiều Hương Cốc Gốm Sứ, Xi Măng, Thủy Tinh Size 100g - 250g",'Raw Data - Sản phẩm'!$B:$B,"Aroma Story - Góc Hương Thơm",'Raw Data - Sản phẩm'!$A:$A,">="&DATE(2026,7,1),'Raw Data - Sản phẩm'!$A:$A,"<="&DATE(2026,7,7)) -> 0 | D14: =IF(B14=0,0,C14/B14) -> 0 | E14: =IF(B14=0,0,D14*(1-'Phí sàn theo shop'!$D$2)) -> 0 | F14: =SUMIFS('Raw Data - Sản phẩm'!$F:$F,'Raw Data - Sản phẩm'!$D:$D,"Nến Thơm Cao Cấp Aroma Story Nhiều Hương Cốc Gốm Sứ, Xi Măng, Thủy Tinh Size 100g - 250g",'Raw Data - Sản phẩm'!$B:$B,"Aroma Story - The Art Of Scent",'Raw Data - Sản phẩm'!$A:$A,">="&DATE(2026,7,1),'Raw Data - Sản phẩm'!$A:$A,"<="&DATE(2026,7,7)) -> 2027726 | G14: =SUMIFS('Raw Data - Sản phẩm'!$G:$G,'Raw Data - Sản phẩm'!$D:$D,"Nến Thơm Cao Cấp Aroma Story Nhiều Hương Cốc Gốm Sứ, Xi Măng, Thủy Tinh Size 100g - 250g",'Raw Data - Sản phẩm'!$B:$B,"Aroma Story - The Art Of Scent",'Raw Data - Sản phẩm'!$A:$A,">="&DATE(2026,7,1),'Raw Data - Sản phẩm'!$A:$A,"<="&DATE(2026,7,7)) -> 10305803 | H14: =IF(F14=0,0,G14/F14) -> 5.0824436 | I14: =IF(F14=0,0,H14*(1-'Phí sàn theo shop'!$D$3)) -> 3.5023571 | J14: =IF(OR(B14=0,F14=0),IF(B14=0,"Chỉ TAOS có data",IF(F14=0,"Chỉ GHT có data","-")),IF(ABS(E14-I14)/MAX(E14,I14)<0.03,"Ngang nhau -> uu tien GHT",IF(E14>I14,"Don ve GHT","Don ve TAOS"))) -> Chỉ TAOS có data
A15: Nến Thơm Cao Cấp Thư Giãn Dễ Ngủ Với Nhiều Hương, Cốc Thủy Tinh & Xi Măng Size 200g | B15: =SUMIFS('Raw Data - Sản phẩm'!$F:$F,'Raw Data - Sản phẩm'!$D:$D,"Nến Thơm Cao Cấp Thư Giãn Dễ Ngủ Với Nhiều Hương, Cốc Thủy Tinh & Xi Măng Size 200g",'Raw Data - Sản phẩm'!$B:$B,"Aroma Story - Góc Hương Thơm",'Raw Data - Sản phẩm'!$A:$A,">="&DATE(2026,7,1),'Raw Data - Sản phẩm'!$A:$A,"<="&DATE(2026,7,7)) -> 1618746 | C15: =SUMIFS('Raw Data - Sản phẩm'!$G:$G,'Raw Data - Sản phẩm'!$D:$D,"Nến Thơm Cao Cấp Thư Giãn Dễ Ngủ Với Nhiều Hương, Cốc Thủy Tinh & Xi Măng Size 200g",'Raw Data - Sản phẩm'!$B:$B,"Aroma Story - Góc Hương Thơm",'Raw Data - Sản phẩm'!$A:$A,">="&DATE(2026,7,1),'Raw Data - Sản phẩm'!$A:$A,"<="&DATE(2026,7,7)) -> 6601458 | D15: =IF(B15=0,0,C15/B15) -> 4.0781308 | E15: =IF(B15=0,0,D15*(1-'Phí sàn theo shop'!$D$2)) -> 3.114003 | F15: =SUMIFS('Raw Data - Sản phẩm'!$F:$F,'Raw Data - Sản phẩm'!$D:$D,"Nến Thơm Cao Cấp Thư Giãn Dễ Ngủ Với Nhiều Hương, Cốc Thủy Tinh & Xi Măng Size 200g",'Raw Data - Sản phẩm'!$B:$B,"Aroma Story - The Art Of Scent",'Raw Data - Sản phẩm'!$A:$A,">="&DATE(2026,7,1),'Raw Data - Sản phẩm'!$A:$A,"<="&DATE(2026,7,7)) -> 0 | G15: =SUMIFS('Raw Data - Sản phẩm'!$G:$G,'Raw Data - Sản phẩm'!$D:$D,"Nến Thơm Cao Cấp Thư Giãn Dễ Ngủ Với Nhiều Hương, Cốc Thủy Tinh & Xi Măng Size 200g",'Raw Data - Sản phẩm'!$B:$B,"Aroma Story - The Art Of Scent",'Raw Data - Sản phẩm'!$A:$A,">="&DATE(2026,7,1),'Raw Data - Sản phẩm'!$A:$A,"<="&DATE(2026,7,7)) -> 0 | H15: =IF(F15=0,0,G15/F15) -> 0 | I15: =IF(F15=0,0,H15*(1-'Phí sàn theo shop'!$D$3)) -> 0 | J15: =IF(OR(B15=0,F15=0),IF(B15=0,"Chỉ TAOS có data",IF(F15=0,"Chỉ GHT có data","-")),IF(ABS(E15-I15)/MAX(E15,I15)<0.03,"Ngang nhau -> uu tien GHT",IF(E15>I15,"Don ve GHT","Don ve TAOS"))) -> Chỉ GHT có data
A16: Nến Thơm Quà Tặng Aroma Story Cho Bạn Bè, Người Yêu Nhân Dịp Sinh Nhật, Kỷ Niệm Và Tốt Nghiệp | B16: =SUMIFS('Raw Data - Sản phẩm'!$F:$F,'Raw Data - Sản phẩm'!$D:$D,"Nến Thơm Quà Tặng Aroma Story Cho Bạn Bè, Người Yêu Nhân Dịp Sinh Nhật, Kỷ Niệm Và Tốt Nghiệp",'Raw Data - Sản phẩm'!$B:$B,"Aroma Story - Góc Hương Thơm",'Raw Data - Sản phẩm'!$A:$A,">="&DATE(2026,7,1),'Raw Data - Sản phẩm'!$A:$A,"<="&DATE(2026,7,7)) -> 0 | C16: =SUMIFS('Raw Data - Sản phẩm'!$G:$G,'Raw Data - Sản phẩm'!$D:$D,"Nến Thơm Quà Tặng Aroma Story Cho Bạn Bè, Người Yêu Nhân Dịp Sinh Nhật, Kỷ Niệm Và Tốt Nghiệp",'Raw Data - Sản phẩm'!$B:$B,"Aroma Story - Góc Hương Thơm",'Raw Data - Sản phẩm'!$A:$A,">="&DATE(2026,7,1),'Raw Data - Sản phẩm'!$A:$A,"<="&DATE(2026,7,7)) -> 0 | D16: =IF(B16=0,0,C16/B16) -> 0 | E16: =IF(B16=0,0,D16*(1-'Phí sàn theo shop'!$D$2)) -> 0 | F16: =SUMIFS('Raw Data - Sản phẩm'!$F:$F,'Raw Data - Sản phẩm'!$D:$D,"Nến Thơm Quà Tặng Aroma Story Cho Bạn Bè, Người Yêu Nhân Dịp Sinh Nhật, Kỷ Niệm Và Tốt Nghiệp",'Raw Data - Sản phẩm'!$B:$B,"Aroma Story - The Art Of Scent",'Raw Data - Sản phẩm'!$A:$A,">="&DATE(2026,7,1),'Raw Data - Sản phẩm'!$A:$A,"<="&DATE(2026,7,7)) -> 0 | G16: =SUMIFS('Raw Data - Sản phẩm'!$G:$G,'Raw Data - Sản phẩm'!$D:$D,"Nến Thơm Quà Tặng Aroma Story Cho Bạn Bè, Người Yêu Nhân Dịp Sinh Nhật, Kỷ Niệm Và Tốt Nghiệp",'Raw Data - Sản phẩm'!$B:$B,"Aroma Story - The Art Of Scent",'Raw Data - Sản phẩm'!$A:$A,">="&DATE(2026,7,1),'Raw Data - Sản phẩm'!$A:$A,"<="&DATE(2026,7,7)) -> 0 | H16: =IF(F16=0,0,G16/F16) -> 0 | I16: =IF(F16=0,0,H16*(1-'Phí sàn theo shop'!$D$3)) -> 0 | J16: =IF(OR(B16=0,F16=0),IF(B16=0,"Chỉ TAOS có data",IF(F16=0,"Chỉ GHT có data","-")),IF(ABS(E16-I16)/MAX(E16,I16)<0.03,"Ngang nhau -> uu tien GHT",IF(E16>I16,"Don ve GHT","Don ve TAOS"))) -> Chỉ TAOS có data
A17: Nến Thơm Quà Tặng Aroma Story Dành Tặng Dịp Sinh Nhật, Kỷ Niệm Cho Nữ, Nam Người Thân Và Bạn Bè | B17: =SUMIFS('Raw Data - Sản phẩm'!$F:$F,'Raw Data - Sản phẩm'!$D:$D,"Nến Thơm Quà Tặng Aroma Story Dành Tặng Dịp Sinh Nhật, Kỷ Niệm Cho Nữ, Nam Người Thân Và Bạn Bè",'Raw Data - Sản phẩm'!$B:$B,"Aroma Story - Góc Hương Thơm",'Raw Data - Sản phẩm'!$A:$A,">="&DATE(2026,7,1),'Raw Data - Sản phẩm'!$A:$A,"<="&DATE(2026,7,7)) -> 0 | C17: =SUMIFS('Raw Data - Sản phẩm'!$G:$G,'Raw Data - Sản phẩm'!$D:$D,"Nến Thơm Quà Tặng Aroma Story Dành Tặng Dịp Sinh Nhật, Kỷ Niệm Cho Nữ, Nam Người Thân Và Bạn Bè",'Raw Data - Sản phẩm'!$B:$B,"Aroma Story - Góc Hương Thơm",'Raw Data - Sản phẩm'!$A:$A,">="&DATE(2026,7,1),'Raw Data - Sản phẩm'!$A:$A,"<="&DATE(2026,7,7)) -> 0 | D17: =IF(B17=0,0,C17/B17) -> 0 | E17: =IF(B17=0,0,D17*(1-'Phí sàn theo shop'!$D$2)) -> 0 | F17: =SUMIFS('Raw Data - Sản phẩm'!$F:$F,'Raw Data - Sản phẩm'!$D:$D,"Nến Thơm Quà Tặng Aroma Story Dành Tặng Dịp Sinh Nhật, Kỷ Niệm Cho Nữ, Nam Người Thân Và Bạn Bè",'Raw Data - Sản phẩm'!$B:$B,"Aroma Story - The Art Of Scent",'Raw Data - Sản phẩm'!$A:$A,">="&DATE(2026,7,1),'Raw Data - Sản phẩm'!$A:$A,"<="&DATE(2026,7,7)) -> 0 | G17: =SUMIFS('Raw Data - Sản phẩm'!$G:$G,'Raw Data - Sản phẩm'!$D:$D,"Nến Thơm Quà Tặng Aroma Story Dành Tặng Dịp Sinh Nhật, Kỷ Niệm Cho Nữ, Nam Người Thân Và Bạn Bè",'Raw Data - Sản phẩm'!$B:$B,"Aroma Story - The Art Of Scent",'Raw Data - Sản phẩm'!$A:$A,">="&DATE(2026,7,1),'Raw Data - Sản phẩm'!$A:$A,"<="&DATE(2026,7,7)) -> 0 | H17: =IF(F17=0,0,G17/F17) -> 0 | I17: =IF(F17=0,0,H17*(1-'Phí sàn theo shop'!$D$3)) -> 0 | J17: =IF(OR(B17=0,F17=0),IF(B17=0,"Chỉ TAOS có data",IF(F17=0,"Chỉ GHT có data","-")),IF(ABS(E17-I17)/MAX(E17,I17)<0.03,"Ngang nhau -> uu tien GHT",IF(E17>I17,"Don ve GHT","Don ve TAOS"))) -> Chỉ TAOS có data
A18: Nến Thơm Thiên Nhiên Bộ Sưu Tập Little Things Aroma Story Size 50g | B18: =SUMIFS('Raw Data - Sản phẩm'!$F:$F,'Raw Data - Sản phẩm'!$D:$D,"Nến Thơm Thiên Nhiên Bộ Sưu Tập Little Things Aroma Story Size 50g",'Raw Data - Sản phẩm'!$B:$B,"Aroma Story - Góc Hương Thơm",'Raw Data - Sản phẩm'!$A:$A,">="&DATE(2026,7,1),'Raw Data - Sản phẩm'!$A:$A,"<="&DATE(2026,7,7)) -> 821314 | C18: =SUMIFS('Raw Data - Sản phẩm'!$G:$G,'Raw Data - Sản phẩm'!$D:$D,"Nến Thơm Thiên Nhiên Bộ Sưu Tập Little Things Aroma Story Size 50g",'Raw Data - Sản phẩm'!$B:$B,"Aroma Story - Góc Hương Thơm",'Raw Data - Sản phẩm'!$A:$A,">="&DATE(2026,7,1),'Raw Data - Sản phẩm'!$A:$A,"<="&DATE(2026,7,7)) -> 3721118 | D18: =IF(B18=0,0,C18/B18) -> 4.5306886 | E18: =IF(B18=0,0,D18*(1-'Phí sàn theo shop'!$D$2)) -> 3.4595697 | F18: =SUMIFS('Raw Data - Sản phẩm'!$F:$F,'Raw Data - Sản phẩm'!$D:$D,"Nến Thơm Thiên Nhiên Bộ Sưu Tập Little Things Aroma Story Size 50g",'Raw Data - Sản phẩm'!$B:$B,"Aroma Story - The Art Of Scent",'Raw Data - Sản phẩm'!$A:$A,">="&DATE(2026,7,1),'Raw Data - Sản phẩm'!$A:$A,"<="&DATE(2026,7,7)) -> 16061 | G18: =SUMIFS('Raw Data - Sản phẩm'!$G:$G,'Raw Data - Sản phẩm'!$D:$D,"Nến Thơm Thiên Nhiên Bộ Sưu Tập Little Things Aroma Story Size 50g",'Raw Data - Sản phẩm'!$B:$B,"Aroma Story - The Art Of Scent",'Raw Data - Sản phẩm'!$A:$A,">="&DATE(2026,7,1),'Raw Data - Sản phẩm'!$A:$A,"<="&DATE(2026,7,7)) -> 0 | H18: =IF(F18=0,0,G18/F18) -> 0 | I18: =IF(F18=0,0,H18*(1-'Phí sàn theo shop'!$D$3)) -> 0 | J18: =IF(OR(B18=0,F18=0),IF(B18=0,"Chỉ TAOS có data",IF(F18=0,"Chỉ GHT có data","-")),IF(ABS(E18-I18)/MAX(E18,I18)<0.03,"Ngang nhau -> uu tien GHT",IF(E18>I18,"Don ve GHT","Don ve TAOS"))) -> Don ve GHT
A19: SET Quà "NẾN THƠM KHẮC TÊN THEO YÊU CẦU" Aroma Story, Dùng Làm Quà Tặng Dịp Đặc Biệt, Sinh Nhật, 20/10, Tốt Nghiệp,... | B19: =SUMIFS('Raw Data - Sản phẩm'!$F:$F,'Raw Data - Sản phẩm'!$D:$D,"SET Quà ""NẾN THƠM KHẮC TÊN THEO YÊU CẦU"" Aroma Story, Dùng Làm Quà Tặng Dịp Đặc Biệt, Sinh Nhật, 20/10, Tốt Nghiệp,...",'Raw Data - Sản phẩm'!$B:$B,"Aroma Story - Góc Hương Thơm",'Raw Data - Sản phẩm'!$A:$A,">="&DATE(2026,7,1),'Raw Data - Sản phẩm'!$A:$A,"<="&DATE(2026,7,7)) -> 0 | C19: =SUMIFS('Raw Data - Sản phẩm'!$G:$G,'Raw Data - Sản phẩm'!$D:$D,"SET Quà ""NẾN THƠM KHẮC TÊN THEO YÊU CẦU"" Aroma Story, Dùng Làm Quà Tặng Dịp Đặc Biệt, Sinh Nhật, 20/10, Tốt Nghiệp,...",'Raw Data - Sản phẩm'!$B:$B,"Aroma Story - Góc Hương Thơm",'Raw Data - Sản phẩm'!$A:$A,">="&DATE(2026,7,1),'Raw Data - Sản phẩm'!$A:$A,"<="&DATE(2026,7,7)) -> 0 | D19: =IF(B19=0,0,C19/B19) -> 0 | E19: =IF(B19=0,0,D19*(1-'Phí sàn theo shop'!$D$2)) -> 0 | F19: =SUMIFS('Raw Data - Sản phẩm'!$F:$F,'Raw Data - Sản phẩm'!$D:$D,"SET Quà ""NẾN THƠM KHẮC TÊN THEO YÊU CẦU"" Aroma Story, Dùng Làm Quà Tặng Dịp Đặc Biệt, Sinh Nhật, 20/10, Tốt Nghiệp,...",'Raw Data - Sản phẩm'!$B:$B,"Aroma Story - The Art Of Scent",'Raw Data - Sản phẩm'!$A:$A,">="&DATE(2026,7,1),'Raw Data - Sản phẩm'!$A:$A,"<="&DATE(2026,7,7)) -> 2153529 | G19: =SUMIFS('Raw Data - Sản phẩm'!$G:$G,'Raw Data - Sản phẩm'!$D:$D,"SET Quà ""NẾN THƠM KHẮC TÊN THEO YÊU CẦU"" Aroma Story, Dùng Làm Quà Tặng Dịp Đặc Biệt, Sinh Nhật, 20/10, Tốt Nghiệp,...",'Raw Data - Sản phẩm'!$B:$B,"Aroma Story - The Art Of Scent",'Raw Data - Sản phẩm'!$A:$A,">="&DATE(2026,7,1),'Raw Data - Sản phẩm'!$A:$A,"<="&DATE(2026,7,7)) -> 11462040 | H19: =IF(F19=0,0,G19/F19) -> 5.3224452 | I19: =IF(F19=0,0,H19*(1-'Phí sàn theo shop'!$D$3)) -> 3.6677443 | J19: =IF(OR(B19=0,F19=0),IF(B19=0,"Chỉ TAOS có data",IF(F19=0,"Chỉ GHT có data","-")),IF(ABS(E19-I19)/MAX(E19,I19)<0.03,"Ngang nhau -> uu tien GHT",IF(E19>I19,"Don ve GHT","Don ve TAOS"))) -> Chỉ TAOS có data
A20: Set Quà Nến Thơm Aroma Story Kèm Phụ Kiện - Quà Sinh Nhật, Kỷ Niệm, Tặng Người Yêu, Bạn Bè | B20: =SUMIFS('Raw Data - Sản phẩm'!$F:$F,'Raw Data - Sản phẩm'!$D:$D,"Set Quà Nến Thơm Aroma Story Kèm Phụ Kiện - Quà Sinh Nhật, Kỷ Niệm, Tặng Người Yêu, Bạn Bè",'Raw Data - Sản phẩm'!$B:$B,"Aroma Story - Góc Hương Thơm",'Raw Data - Sản phẩm'!$A:$A,">="&DATE(2026,7,1),'Raw Data - Sản phẩm'!$A:$A,"<="&DATE(2026,7,7)) -> 0 | C20: =SUMIFS('Raw Data - Sản phẩm'!$G:$G,'Raw Data - Sản phẩm'!$D:$D,"Set Quà Nến Thơm Aroma Story Kèm Phụ Kiện - Quà Sinh Nhật, Kỷ Niệm, Tặng Người Yêu, Bạn Bè",'Raw Data - Sản phẩm'!$B:$B,"Aroma Story - Góc Hương Thơm",'Raw Data - Sản phẩm'!$A:$A,">="&DATE(2026,7,1),'Raw Data - Sản phẩm'!$A:$A,"<="&DATE(2026,7,7)) -> 0 | D20: =IF(B20=0,0,C20/B20) -> 0 | E20: =IF(B20=0,0,D20*(1-'Phí sàn theo shop'!$D$2)) -> 0 | F20: =SUMIFS('Raw Data - Sản phẩm'!$F:$F,'Raw Data - Sản phẩm'!$D:$D,"Set Quà Nến Thơm Aroma Story Kèm Phụ Kiện - Quà Sinh Nhật, Kỷ Niệm, Tặng Người Yêu, Bạn Bè",'Raw Data - Sản phẩm'!$B:$B,"Aroma Story - The Art Of Scent",'Raw Data - Sản phẩm'!$A:$A,">="&DATE(2026,7,1),'Raw Data - Sản phẩm'!$A:$A,"<="&DATE(2026,7,7)) -> 0 | G20: =SUMIFS('Raw Data - Sản phẩm'!$G:$G,'Raw Data - Sản phẩm'!$D:$D,"Set Quà Nến Thơm Aroma Story Kèm Phụ Kiện - Quà Sinh Nhật, Kỷ Niệm, Tặng Người Yêu, Bạn Bè",'Raw Data - Sản phẩm'!$B:$B,"Aroma Story - The Art Of Scent",'Raw Data - Sản phẩm'!$A:$A,">="&DATE(2026,7,1),'Raw Data - Sản phẩm'!$A:$A,"<="&DATE(2026,7,7)) -> 0 | H20: =IF(F20=0,0,G20/F20) -> 0 | I20: =IF(F20=0,0,H20*(1-'Phí sàn theo shop'!$D$3)) -> 0 | J20: =IF(OR(B20=0,F20=0),IF(B20=0,"Chỉ TAOS có data",IF(F20=0,"Chỉ GHT có data","-")),IF(ABS(E20-I20)/MAX(E20,I20)<0.03,"Ngang nhau -> uu tien GHT",IF(E20>I20,"Don ve GHT","Don ve TAOS"))) -> Chỉ TAOS có data
A21: Set Quà Tặng Nến Thơm Aroma Story Dành Tặng Người Yêu, Sinh Nhật, Kỷ Niệm | B21: =SUMIFS('Raw Data - Sản phẩm'!$F:$F,'Raw Data - Sản phẩm'!$D:$D,"Set Quà Tặng Nến Thơm Aroma Story Dành Tặng Người Yêu, Sinh Nhật, Kỷ Niệm",'Raw Data - Sản phẩm'!$B:$B,"Aroma Story - Góc Hương Thơm",'Raw Data - Sản phẩm'!$A:$A,">="&DATE(2026,7,1),'Raw Data - Sản phẩm'!$A:$A,"<="&DATE(2026,7,7)) -> 358850 | C21: =SUMIFS('Raw Data - Sản phẩm'!$G:$G,'Raw Data - Sản phẩm'!$D:$D,"Set Quà Tặng Nến Thơm Aroma Story Dành Tặng Người Yêu, Sinh Nhật, Kỷ Niệm",'Raw Data - Sản phẩm'!$B:$B,"Aroma Story - Góc Hương Thơm",'Raw Data - Sản phẩm'!$A:$A,">="&DATE(2026,7,1),'Raw Data - Sản phẩm'!$A:$A,"<="&DATE(2026,7,7)) -> 1404117 | D21: =IF(B21=0,0,C21/B21) -> 3.9128243 | E21: =IF(B21=0,0,D21*(1-'Phí sàn theo shop'!$D$2)) -> 2.9877772 | F21: =SUMIFS('Raw Data - Sản phẩm'!$F:$F,'Raw Data - Sản phẩm'!$D:$D,"Set Quà Tặng Nến Thơm Aroma Story Dành Tặng Người Yêu, Sinh Nhật, Kỷ Niệm",'Raw Data - Sản phẩm'!$B:$B,"Aroma Story - The Art Of Scent",'Raw Data - Sản phẩm'!$A:$A,">="&DATE(2026,7,1),'Raw Data - Sản phẩm'!$A:$A,"<="&DATE(2026,7,7)) -> 0 | G21: =SUMIFS('Raw Data - Sản phẩm'!$G:$G,'Raw Data - Sản phẩm'!$D:$D,"Set Quà Tặng Nến Thơm Aroma Story Dành Tặng Người Yêu, Sinh Nhật, Kỷ Niệm",'Raw Data - Sản phẩm'!$B:$B,"Aroma Story - The Art Of Scent",'Raw Data - Sản phẩm'!$A:$A,">="&DATE(2026,7,1),'Raw Data - Sản phẩm'!$A:$A,"<="&DATE(2026,7,7)) -> 0 | H21: =IF(F21=0,0,G21/F21) -> 0 | I21: =IF(F21=0,0,H21*(1-'Phí sàn theo shop'!$D$3)) -> 0 | J21: =IF(OR(B21=0,F21=0),IF(B21=0,"Chỉ TAOS có data",IF(F21=0,"Chỉ GHT có data","-")),IF(ABS(E21-I21)/MAX(E21,I21)<0.03,"Ngang nhau -> uu tien GHT",IF(E21>I21,"Don ve GHT","Don ve TAOS"))) -> Chỉ GHT có data
A22: Tinh Dầu Thiên Nhiên Hương Trà Trắng Aroma Story Nguyên Chất – Xông Phòng, Thư Giãn, Ngủ Ngon 10ml | B22: =SUMIFS('Raw Data - Sản phẩm'!$F:$F,'Raw Data - Sản phẩm'!$D:$D,"Tinh Dầu Thiên Nhiên Hương Trà Trắng Aroma Story Nguyên Chất – Xông Phòng, Thư Giãn, Ngủ Ngon 10ml",'Raw Data - Sản phẩm'!$B:$B,"Aroma Story - Góc Hương Thơm",'Raw Data - Sản phẩm'!$A:$A,">="&DATE(2026,7,1),'Raw Data - Sản phẩm'!$A:$A,"<="&DATE(2026,7,7)) -> 0 | C22: =SUMIFS('Raw Data - Sản phẩm'!$G:$G,'Raw Data - Sản phẩm'!$D:$D,"Tinh Dầu Thiên Nhiên Hương Trà Trắng Aroma Story Nguyên Chất – Xông Phòng, Thư Giãn, Ngủ Ngon 10ml",'Raw Data - Sản phẩm'!$B:$B,"Aroma Story - Góc Hương Thơm",'Raw Data - Sản phẩm'!$A:$A,">="&DATE(2026,7,1),'Raw Data - Sản phẩm'!$A:$A,"<="&DATE(2026,7,7)) -> 0 | D22: =IF(B22=0,0,C22/B22) -> 0 | E22: =IF(B22=0,0,D22*(1-'Phí sàn theo shop'!$D$2)) -> 0 | F22: =SUMIFS('Raw Data - Sản phẩm'!$F:$F,'Raw Data - Sản phẩm'!$D:$D,"Tinh Dầu Thiên Nhiên Hương Trà Trắng Aroma Story Nguyên Chất – Xông Phòng, Thư Giãn, Ngủ Ngon 10ml",'Raw Data - Sản phẩm'!$B:$B,"Aroma Story - The Art Of Scent",'Raw Data - Sản phẩm'!$A:$A,">="&DATE(2026,7,1),'Raw Data - Sản phẩm'!$A:$A,"<="&DATE(2026,7,7)) -> 0 | G22: =SUMIFS('Raw Data - Sản phẩm'!$G:$G,'Raw Data - Sản phẩm'!$D:$D,"Tinh Dầu Thiên Nhiên Hương Trà Trắng Aroma Story Nguyên Chất – Xông Phòng, Thư Giãn, Ngủ Ngon 10ml",'Raw Data - Sản phẩm'!$B:$B,"Aroma Story - The Art Of Scent",'Raw Data - Sản phẩm'!$A:$A,">="&DATE(2026,7,1),'Raw Data - Sản phẩm'!$A:$A,"<="&DATE(2026,7,7)) -> 0 | H22: =IF(F22=0,0,G22/F22) -> 0 | I22: =IF(F22=0,0,H22*(1-'Phí sàn theo shop'!$D$3)) -> 0 | J22: =IF(OR(B22=0,F22=0),IF(B22=0,"Chỉ TAOS có data",IF(F22=0,"Chỉ GHT có data","-")),IF(ABS(E22-I22)/MAX(E22,I22)<0.03,"Ngang nhau -> uu tien GHT",IF(E22>I22,"Don ve GHT","Don ve TAOS"))) -> Chỉ TAOS có data
